1
2
3
4
5
6
7
8
9
10
11
12
13
14
15
16
17
18
19
20
21
22
23
24
25
26
27
28
29
30
/Users/visriv/Library/Python/3.9/lib/python/site-packages/torch/nn/functional.py:1967: UserWarning: nn.functional.sigmoid is deprecated. Use torch.sigmoid instead.
  warnings.warn("nn.functional.sigmoid is deprecated. Use torch.sigmoid instead.")
31
32
33
34
35
36
37
38
39
40
41
42
43
44
45
46
47
48
49
50
51
52
53
1
2
3
4
5
6
7
8
9
10
11
12
13
14
15
16
17
18
19
20
21
22
23
24
25
26
27
28
29
30
31
32
33
34
35
36
37
38
39
40
41
42
43
44
45
46
47
48
49
50
51
52
53
54
55
56
57
58
59
60
61
62
63
64
65
66
67
68
69
70
71
72
73
74
75
76
77
78
79
80
81
82
83
84
85
86
87
88
89
90
91
92
93
94
95
96
97
98
99
100
[iteration 100] time: 0.07 	beta 1.00 	lambda 0.00 training ELBO: -176.3947 (-231.8684)
/Users/visriv/Documents/Git/beta-tcvae/plot_latent_vs_true.py:206: UserWarning: volatile was removed and now has no effect. Use `with torch.no_grad():` instead.
  xs = Variable(xs.view(batch_size, 1, 28, 28), volatile=True)
Active units: 0,1,2,3,4,5,6,7,8,9
Number of active units: 10/10
101
102
103
104
105
106
107
108
109
110
111
112
113
114
115
116
117
118
119
120
121
122
123
124
125
126
127
128
129
130
131
132
133
134
135
136
137
138
139
140
141
142
143
144
145
146
147
148
149
150
151
152
153
154
155
156
157
158
159
160
161
162
163
164
165
166
167
168
169
170
171
172
173
174
175
176
177
178
179
180
181
182
183
184
185
186
187
188
189
190
191
192
193
194
195
196
197
198
199
200
[iteration 200] time: 0.04 	beta 1.00 	lambda 0.00 training ELBO: -170.4039 (-164.0021)
Active units: 0,1,2,3,4,5,6,7,8,9
Number of active units: 10/10
201
202
203
204
205
206
207
208
209
210
211
212
213
214
215
216
217
218
219
220
221
222
223
224
225
226
227
228
229
230
231
232
233
234
235
236
237
238
239
240
241
242
243
244
245
246
247
248
249
250
251
252
253
254
255
256
257
258
259
260
261
262
263
264
265
266
267
268
269
270
271
272
273
274
275
276
277
278
279
280
281
282
283
284
285
286
287
288
289
290
291
292
293
294
295
296
297
298
299
300
[iteration 300] time: 0.05 	beta 1.00 	lambda 0.00 training ELBO: -140.1550 (-147.4845)
Active units: 0,1,2,3,4,5,6,7,8,9
Number of active units: 10/10
301
302
303
304
305
306
307
308
309
310
311
312
313
314
315
316
317
318
319
320
321
322
323
324
325
326
327
328
329
330
331
332
333
334
335
336
337
338
339
340
341
342
343
344
345
346
347
348
349
350
351
352
353
354
355
356
357
358
359
360
361
362
363
364
365
366
367
368
369
370
371
372
373
374
375
376
377
378
379
380
381
382
383
384
385
386
387
388
389
390
391
392
393
394
395
396
397
398
399
400
[iteration 400] time: 0.04 	beta 1.00 	lambda 0.00 training ELBO: -126.5084 (-139.4290)
Active units: 0,1,2,3,4,5,6,7,8,9
Number of active units: 10/10
401
402
403
404
405
406
407
408
409
410
411
412
413
414
415
416
417
418
419
420
421
422
423
424
425
426
427
428
429
430
431
432
433
434
435
436
437
438
439
440
441
442
443
444
445
446
447
448
449
450
451
452
453
454
455
456
457
458
459
460
461
462
463
464
465
466
467
468
469
470
471
472
473
474
475
476
477
478
479
480
481
482
483
484
485
486
487
488
489
490
491
492
493
494
495
496
497
498
499
500
[iteration 500] time: 0.04 	beta 1.00 	lambda 0.00 training ELBO: -144.3600 (-135.4480)
Active units: 0,1,2,3,4,5,6,7,8,9
Number of active units: 10/10
501
502
503
504
505
506
507
508
509
510
511
512
513
514
515
516
517
518
519
520
521
522
523
524
525
526
527
528
529
530
531
532
533
534
535
536
537
538
539
540
541
542
543
544
545
546
547
548
549
550
551
552
553
554
555
556
557
558
559
560
561
562
563
564
565
566
567
568
569
570
571
572
573
574
575
576
577
578
579
580
581
582
583
584
585
586
587
588
589
590
591
592
593
594
595
596
597
598
599
600
[iteration 600] time: 0.05 	beta 1.00 	lambda 0.00 training ELBO: -134.1680 (-132.9342)
Active units: 0,1,2,3,4,5,6,7,8,9
Number of active units: 10/10
601
602
603
604
605
606
607
608
609
610
611
612
613
614
615
616
617
618
619
620
621
622
623
624
625
626
627
628
629
630
631
632
633
634
635
636
637
638
639
640
641
642
643
644
645
646
647
648
649
650
651
652
653
654
655
656
657
658
659
660
661
662
663
664
665
666
667
668
669
670
671
672
673
674
675
676
677
678
679
680
681
682
683
684
685
686
687
688
689
690
691
692
693
694
695
696
697
698
699
700
[iteration 700] time: 0.04 	beta 1.00 	lambda 0.00 training ELBO: -121.0435 (-129.2569)
Defaulting to user installation because normal site-packages is not writeable
Requirement already satisfied: visdom in /Users/visriv/Library/Python/3.9/lib/python/site-packages (0.2.4)
Requirement already satisfied: jsonpatch in /Users/visriv/Library/Python/3.9/lib/python/site-packages (from visdom) (1.32)
Requirement already satisfied: scipy in /Users/visriv/Library/Python/3.9/lib/python/site-packages (from visdom) (1.10.1)
Requirement already satisfied: six in /Library/Developer/CommandLineTools/Library/Frameworks/Python3.framework/Versions/3.9/lib/python3.9/site-packages (from visdom) (1.15.0)
Requirement already satisfied: pillow in /Users/visriv/Library/Python/3.9/lib/python/site-packages (from visdom) (9.4.0)
Requirement already satisfied: numpy>=1.8 in /Users/visriv/Library/Python/3.9/lib/python/site-packages (from visdom) (1.24.1)
Requirement already satisfied: websocket-client in /Users/visriv/Library/Python/3.9/lib/python/site-packages (from visdom) (1.5.1)
Requirement already satisfied: networkx in /Users/visriv/Library/Python/3.9/lib/python/site-packages (from visdom) (3.0)
Requirement already satisfied: requests in /Users/visriv/Library/Python/3.9/lib/python/site-packages (from visdom) (2.28.2)
Requirement already satisfied: tornado in /Users/visriv/Library/Python/3.9/lib/python/site-packages (from visdom) (6.2)
Requirement already satisfied: jsonpointer>=1.9 in /Users/visriv/Library/Python/3.9/lib/python/site-packages (from jsonpatch->visdom) (2.3)
Requirement already satisfied: urllib3<1.27,>=1.21.1 in /Users/visriv/Library/Python/3.9/lib/python/site-packages (from requests->visdom) (1.26.14)
Requirement already satisfied: charset-normalizer<4,>=2 in /Users/visriv/Library/Python/3.9/lib/python/site-packages (from requests->visdom) (2.1.1)
Requirement already satisfied: idna<4,>=2.5 in /Users/visriv/Library/Python/3.9/lib/python/site-packages (from requests->visdom) (3.4)
Requirement already satisfied: certifi>=2017.4.17 in /Users/visriv/Library/Python/3.9/lib/python/site-packages (from requests->visdom) (2022.12.7)
[1m[[34m[22mnotice[39m[1m][22m A new release of pip is available: [31m23.0[39m -> [32m23.0.1
[1m[[34m[22mnotice[39m[1m][22m To update, run: [32m/Library/Developer/CommandLineTools/usr/bin/python3 -m pip install --upgrade pip
Setting up a new session...
Traceback (most recent call last):
  File "/Users/visriv/Library/Python/3.9/lib/python/site-packages/urllib3/connection.py", line 174, in _new_conn
    conn = connection.create_connection(
  File "/Users/visriv/Library/Python/3.9/lib/python/site-packages/urllib3/util/connection.py", line 95, in create_connection
    raise err
  File "/Users/visriv/Library/Python/3.9/lib/python/site-packages/urllib3/util/connection.py", line 85, in create_connection
    sock.connect(sa)
ConnectionRefusedError: [Errno 61] Connection refused
During handling of the above exception, another exception occurred:
Traceback (most recent call last):
  File "/Users/visriv/Library/Python/3.9/lib/python/site-packages/urllib3/connectionpool.py", line 703, in urlopen
    httplib_response = self._make_request(
  File "/Users/visriv/Library/Python/3.9/lib/python/site-packages/urllib3/connectionpool.py", line 398, in _make_request
    conn.request(method, url, **httplib_request_kw)
  File "/Users/visriv/Library/Python/3.9/lib/python/site-packages/urllib3/connection.py", line 239, in request
    super(HTTPConnection, self).request(method, url, body=body, headers=headers)
  File "/Library/Developer/CommandLineTools/Library/Frameworks/Python3.framework/Versions/3.9/lib/python3.9/http/client.py", line 1257, in request
    self._send_request(method, url, body, headers, encode_chunked)
  File "/Library/Developer/CommandLineTools/Library/Frameworks/Python3.framework/Versions/3.9/lib/python3.9/http/client.py", line 1303, in _send_request
    self.endheaders(body, encode_chunked=encode_chunked)
  File "/Library/Developer/CommandLineTools/Library/Frameworks/Python3.framework/Versions/3.9/lib/python3.9/http/client.py", line 1252, in endheaders
    self._send_output(message_body, encode_chunked=encode_chunked)
  File "/Library/Developer/CommandLineTools/Library/Frameworks/Python3.framework/Versions/3.9/lib/python3.9/http/client.py", line 1012, in _send_output
    self.send(msg)
  File "/Library/Developer/CommandLineTools/Library/Frameworks/Python3.framework/Versions/3.9/lib/python3.9/http/client.py", line 952, in send
    self.connect()
  File "/Users/visriv/Library/Python/3.9/lib/python/site-packages/urllib3/connection.py", line 205, in connect
    conn = self._new_conn()
  File "/Users/visriv/Library/Python/3.9/lib/python/site-packages/urllib3/connection.py", line 186, in _new_conn
    raise NewConnectionError(
urllib3.exceptions.NewConnectionError: <urllib3.connection.HTTPConnection object at 0x12420f940>: Failed to establish a new connection: [Errno 61] Connection refused
During handling of the above exception, another exception occurred:
Traceback (most recent call last):
  File "/Users/visriv/Library/Python/3.9/lib/python/site-packages/requests/adapters.py", line 489, in send
    resp = conn.urlopen(
  File "/Users/visriv/Library/Python/3.9/lib/python/site-packages/urllib3/connectionpool.py", line 787, in urlopen
    retries = retries.increment(
  File "/Users/visriv/Library/Python/3.9/lib/python/site-packages/urllib3/util/retry.py", line 592, in increment
    raise MaxRetryError(_pool, url, error or ResponseError(cause))
urllib3.exceptions.MaxRetryError: HTTPConnectionPool(host='localhost', port=4500): Max retries exceeded with url: /env/test (Caused by NewConnectionError('<urllib3.connection.HTTPConnection object at 0x12420f940>: Failed to establish a new connection: [Errno 61] Connection refused'))
During handling of the above exception, another exception occurred:
Traceback (most recent call last):
  File "/Users/visriv/Library/Python/3.9/lib/python/site-packages/visdom/__init__.py", line 756, in _send
    return self._handle_post(
  File "/Users/visriv/Library/Python/3.9/lib/python/site-packages/visdom/__init__.py", line 720, in _handle_post
    r = self.session.post(url, data=data)
  File "/Users/visriv/Library/Python/3.9/lib/python/site-packages/requests/sessions.py", line 635, in post
    return self.request("POST", url, data=data, json=json, **kwargs)
  File "/Users/visriv/Library/Python/3.9/lib/python/site-packages/requests/sessions.py", line 587, in request
    resp = self.send(prep, **send_kwargs)
  File "/Users/visriv/Library/Python/3.9/lib/python/site-packages/requests/sessions.py", line 701, in send
    r = adapter.send(request, **kwargs)
  File "/Users/visriv/Library/Python/3.9/lib/python/site-packages/requests/adapters.py", line 565, in send
    raise ConnectionError(e, request=request)
requests.exceptions.ConnectionError: HTTPConnectionPool(host='localhost', port=4500): Max retries exceeded with url: /env/test (Caused by NewConnectionError('<urllib3.connection.HTTPConnection object at 0x12420f940>: Failed to establish a new connection: [Errno 61] Connection refused'))
[Errno 61] Connection refused
on_close() takes 1 positional argument but 3 were given
Exception in user code:
------------------------------------------------------------
1
2
3
4
5
6
7
8
9
10
11
12
13
14
15
16
17
18
19
20
21
22
23
24
25
26
27
28
29
30
31
32
33
34
35
36
37
38
39
40
41
42
43
44
45
46
47
48
49
50
51
52
53
54
55
56
57
58
59
60
61
62
63
64
65
66
67
68
69
70
71
72
73
74
75
76
77
78
79
80
81
82
83
84
85
86
87
88
89
90
91
92
93
94
95
96
97
98
99
100
[iteration 100] time: 0.04 	beta 1.00 	lambda 0.00 training ELBO: -208.0996 (-263.3070)
Setting up a new session...
Traceback (most recent call last):
  File "/Users/visriv/Library/Python/3.9/lib/python/site-packages/urllib3/connection.py", line 174, in _new_conn
    conn = connection.create_connection(
  File "/Users/visriv/Library/Python/3.9/lib/python/site-packages/urllib3/util/connection.py", line 95, in create_connection
    raise err
  File "/Users/visriv/Library/Python/3.9/lib/python/site-packages/urllib3/util/connection.py", line 85, in create_connection
    sock.connect(sa)
ConnectionRefusedError: [Errno 61] Connection refused
During handling of the above exception, another exception occurred:
Traceback (most recent call last):
  File "/Users/visriv/Library/Python/3.9/lib/python/site-packages/urllib3/connectionpool.py", line 703, in urlopen
    httplib_response = self._make_request(
  File "/Users/visriv/Library/Python/3.9/lib/python/site-packages/urllib3/connectionpool.py", line 398, in _make_request
    conn.request(method, url, **httplib_request_kw)
  File "/Users/visriv/Library/Python/3.9/lib/python/site-packages/urllib3/connection.py", line 239, in request
    super(HTTPConnection, self).request(method, url, body=body, headers=headers)
  File "/Library/Developer/CommandLineTools/Library/Frameworks/Python3.framework/Versions/3.9/lib/python3.9/http/client.py", line 1257, in request
    self._send_request(method, url, body, headers, encode_chunked)
  File "/Library/Developer/CommandLineTools/Library/Frameworks/Python3.framework/Versions/3.9/lib/python3.9/http/client.py", line 1303, in _send_request
    self.endheaders(body, encode_chunked=encode_chunked)
  File "/Library/Developer/CommandLineTools/Library/Frameworks/Python3.framework/Versions/3.9/lib/python3.9/http/client.py", line 1252, in endheaders
    self._send_output(message_body, encode_chunked=encode_chunked)
  File "/Library/Developer/CommandLineTools/Library/Frameworks/Python3.framework/Versions/3.9/lib/python3.9/http/client.py", line 1012, in _send_output
    self.send(msg)
  File "/Library/Developer/CommandLineTools/Library/Frameworks/Python3.framework/Versions/3.9/lib/python3.9/http/client.py", line 952, in send
    self.connect()
  File "/Users/visriv/Library/Python/3.9/lib/python/site-packages/urllib3/connection.py", line 205, in connect
    conn = self._new_conn()
  File "/Users/visriv/Library/Python/3.9/lib/python/site-packages/urllib3/connection.py", line 186, in _new_conn
    raise NewConnectionError(
urllib3.exceptions.NewConnectionError: <urllib3.connection.HTTPConnection object at 0x1242146a0>: Failed to establish a new connection: [Errno 61] Connection refused
During handling of the above exception, another exception occurred:
Traceback (most recent call last):
  File "/Users/visriv/Library/Python/3.9/lib/python/site-packages/requests/adapters.py", line 489, in send
    resp = conn.urlopen(
  File "/Users/visriv/Library/Python/3.9/lib/python/site-packages/urllib3/connectionpool.py", line 787, in urlopen
    retries = retries.increment(
  File "/Users/visriv/Library/Python/3.9/lib/python/site-packages/urllib3/util/retry.py", line 592, in increment
    raise MaxRetryError(_pool, url, error or ResponseError(cause))
urllib3.exceptions.MaxRetryError: HTTPConnectionPool(host='localhost', port=4500): Max retries exceeded with url: /env/test (Caused by NewConnectionError('<urllib3.connection.HTTPConnection object at 0x1242146a0>: Failed to establish a new connection: [Errno 61] Connection refused'))
During handling of the above exception, another exception occurred:
Traceback (most recent call last):
  File "/Users/visriv/Library/Python/3.9/lib/python/site-packages/visdom/__init__.py", line 756, in _send
    return self._handle_post(
  File "/Users/visriv/Library/Python/3.9/lib/python/site-packages/visdom/__init__.py", line 720, in _handle_post
    r = self.session.post(url, data=data)
  File "/Users/visriv/Library/Python/3.9/lib/python/site-packages/requests/sessions.py", line 635, in post
    return self.request("POST", url, data=data, json=json, **kwargs)
  File "/Users/visriv/Library/Python/3.9/lib/python/site-packages/requests/sessions.py", line 587, in request
    resp = self.send(prep, **send_kwargs)
  File "/Users/visriv/Library/Python/3.9/lib/python/site-packages/requests/sessions.py", line 701, in send
    r = adapter.send(request, **kwargs)
  File "/Users/visriv/Library/Python/3.9/lib/python/site-packages/requests/adapters.py", line 565, in send
    raise ConnectionError(e, request=request)
requests.exceptions.ConnectionError: HTTPConnectionPool(host='localhost', port=4500): Max retries exceeded with url: /env/test (Caused by NewConnectionError('<urllib3.connection.HTTPConnection object at 0x1242146a0>: Failed to establish a new connection: [Errno 61] Connection refused'))
[Errno 61] Connection refused
on_close() takes 1 positional argument but 3 were given
Exception in user code:
------------------------------------------------------------
1
2
3
4
5
6
7
8
9
10
11
12
13
14
15
16
17
18
19
20
21
22
23
24
25
26
27
28
29
30
31
32
33
34
35
36
37
38
39
40
41
42
43
44
45
46
47
48
49
50
51
52
53
54
55
56
57
58
59
60
61
62
63
64
65
66
67
68
69
70
71
72
73
74
75
76
77
78
79
80
81
82
83
84
85
86
87
88
89
90
91
92
93
94
95
96
97
98
99
100
[iteration 100] time: 0.04 	beta 1.00 	lambda 0.00 training ELBO: -185.6637 (-233.0074)
Setting up a new session...
Traceback (most recent call last):
  File "/Users/visriv/Library/Python/3.9/lib/python/site-packages/urllib3/connection.py", line 174, in _new_conn
    conn = connection.create_connection(
  File "/Users/visriv/Library/Python/3.9/lib/python/site-packages/urllib3/util/connection.py", line 95, in create_connection
    raise err
  File "/Users/visriv/Library/Python/3.9/lib/python/site-packages/urllib3/util/connection.py", line 85, in create_connection
    sock.connect(sa)
ConnectionRefusedError: [Errno 61] Connection refused
During handling of the above exception, another exception occurred:
Traceback (most recent call last):
  File "/Users/visriv/Library/Python/3.9/lib/python/site-packages/urllib3/connectionpool.py", line 703, in urlopen
    httplib_response = self._make_request(
  File "/Users/visriv/Library/Python/3.9/lib/python/site-packages/urllib3/connectionpool.py", line 398, in _make_request
    conn.request(method, url, **httplib_request_kw)
  File "/Users/visriv/Library/Python/3.9/lib/python/site-packages/urllib3/connection.py", line 239, in request
    super(HTTPConnection, self).request(method, url, body=body, headers=headers)
  File "/Library/Developer/CommandLineTools/Library/Frameworks/Python3.framework/Versions/3.9/lib/python3.9/http/client.py", line 1257, in request
    self._send_request(method, url, body, headers, encode_chunked)
  File "/Library/Developer/CommandLineTools/Library/Frameworks/Python3.framework/Versions/3.9/lib/python3.9/http/client.py", line 1303, in _send_request
    self.endheaders(body, encode_chunked=encode_chunked)
  File "/Library/Developer/CommandLineTools/Library/Frameworks/Python3.framework/Versions/3.9/lib/python3.9/http/client.py", line 1252, in endheaders
    self._send_output(message_body, encode_chunked=encode_chunked)
  File "/Library/Developer/CommandLineTools/Library/Frameworks/Python3.framework/Versions/3.9/lib/python3.9/http/client.py", line 1012, in _send_output
    self.send(msg)
  File "/Library/Developer/CommandLineTools/Library/Frameworks/Python3.framework/Versions/3.9/lib/python3.9/http/client.py", line 952, in send
    self.connect()
  File "/Users/visriv/Library/Python/3.9/lib/python/site-packages/urllib3/connection.py", line 205, in connect
    conn = self._new_conn()
  File "/Users/visriv/Library/Python/3.9/lib/python/site-packages/urllib3/connection.py", line 186, in _new_conn
    raise NewConnectionError(
urllib3.exceptions.NewConnectionError: <urllib3.connection.HTTPConnection object at 0x13ef53ee0>: Failed to establish a new connection: [Errno 61] Connection refused
During handling of the above exception, another exception occurred:
Traceback (most recent call last):
  File "/Users/visriv/Library/Python/3.9/lib/python/site-packages/requests/adapters.py", line 489, in send
    resp = conn.urlopen(
  File "/Users/visriv/Library/Python/3.9/lib/python/site-packages/urllib3/connectionpool.py", line 787, in urlopen
    retries = retries.increment(
  File "/Users/visriv/Library/Python/3.9/lib/python/site-packages/urllib3/util/retry.py", line 592, in increment
    raise MaxRetryError(_pool, url, error or ResponseError(cause))
urllib3.exceptions.MaxRetryError: HTTPConnectionPool(host='localhost', port=4500): Max retries exceeded with url: /env/test (Caused by NewConnectionError('<urllib3.connection.HTTPConnection object at 0x13ef53ee0>: Failed to establish a new connection: [Errno 61] Connection refused'))
During handling of the above exception, another exception occurred:
Traceback (most recent call last):
  File "/Users/visriv/Library/Python/3.9/lib/python/site-packages/visdom/__init__.py", line 756, in _send
    return self._handle_post(
  File "/Users/visriv/Library/Python/3.9/lib/python/site-packages/visdom/__init__.py", line 720, in _handle_post
    r = self.session.post(url, data=data)
  File "/Users/visriv/Library/Python/3.9/lib/python/site-packages/requests/sessions.py", line 635, in post
    return self.request("POST", url, data=data, json=json, **kwargs)
  File "/Users/visriv/Library/Python/3.9/lib/python/site-packages/requests/sessions.py", line 587, in request
    resp = self.send(prep, **send_kwargs)
  File "/Users/visriv/Library/Python/3.9/lib/python/site-packages/requests/sessions.py", line 701, in send
    r = adapter.send(request, **kwargs)
  File "/Users/visriv/Library/Python/3.9/lib/python/site-packages/requests/adapters.py", line 565, in send
    raise ConnectionError(e, request=request)
requests.exceptions.ConnectionError: HTTPConnectionPool(host='localhost', port=4500): Max retries exceeded with url: /env/test (Caused by NewConnectionError('<urllib3.connection.HTTPConnection object at 0x13ef53ee0>: Failed to establish a new connection: [Errno 61] Connection refused'))
[Errno 61] Connection refused
on_close() takes 1 positional argument but 3 were given
Exception in user code:
------------------------------------------------------------
1
2
3
4
5
6
7
8
9
10
11
12
13
14
15
16
17
18
19
20
21
22
23
24
25
26
27
28
29
30
31
32
33
34
35
36
37
38
39
40
41
42
43
44
45
46
47
48
49
50
51
52
53
54
55
56
57
58
59
60
61
62
63
64
65
66
67
68
69
70
71
72
73
74
75
76
77
78
79
80
81
82
83
84
85
86
87
88
89
90
91
92
93
94
95
96
97
98
99
100
[iteration 100] time: 0.04 	beta 1.00 	lambda 0.00 training ELBO: -185.0370 (-236.5870)
Setting up a new session...
Traceback (most recent call last):
  File "/Users/visriv/Library/Python/3.9/lib/python/site-packages/urllib3/connection.py", line 174, in _new_conn
    conn = connection.create_connection(
  File "/Users/visriv/Library/Python/3.9/lib/python/site-packages/urllib3/util/connection.py", line 95, in create_connection
    raise err
  File "/Users/visriv/Library/Python/3.9/lib/python/site-packages/urllib3/util/connection.py", line 85, in create_connection
    sock.connect(sa)
ConnectionRefusedError: [Errno 61] Connection refused
During handling of the above exception, another exception occurred:
Traceback (most recent call last):
  File "/Users/visriv/Library/Python/3.9/lib/python/site-packages/urllib3/connectionpool.py", line 703, in urlopen
    httplib_response = self._make_request(
  File "/Users/visriv/Library/Python/3.9/lib/python/site-packages/urllib3/connectionpool.py", line 398, in _make_request
    conn.request(method, url, **httplib_request_kw)
  File "/Users/visriv/Library/Python/3.9/lib/python/site-packages/urllib3/connection.py", line 239, in request
    super(HTTPConnection, self).request(method, url, body=body, headers=headers)
  File "/Library/Developer/CommandLineTools/Library/Frameworks/Python3.framework/Versions/3.9/lib/python3.9/http/client.py", line 1257, in request
    self._send_request(method, url, body, headers, encode_chunked)
  File "/Library/Developer/CommandLineTools/Library/Frameworks/Python3.framework/Versions/3.9/lib/python3.9/http/client.py", line 1303, in _send_request
    self.endheaders(body, encode_chunked=encode_chunked)
  File "/Library/Developer/CommandLineTools/Library/Frameworks/Python3.framework/Versions/3.9/lib/python3.9/http/client.py", line 1252, in endheaders
    self._send_output(message_body, encode_chunked=encode_chunked)
  File "/Library/Developer/CommandLineTools/Library/Frameworks/Python3.framework/Versions/3.9/lib/python3.9/http/client.py", line 1012, in _send_output
    self.send(msg)
  File "/Library/Developer/CommandLineTools/Library/Frameworks/Python3.framework/Versions/3.9/lib/python3.9/http/client.py", line 952, in send
    self.connect()
  File "/Users/visriv/Library/Python/3.9/lib/python/site-packages/urllib3/connection.py", line 205, in connect
    conn = self._new_conn()
  File "/Users/visriv/Library/Python/3.9/lib/python/site-packages/urllib3/connection.py", line 186, in _new_conn
    raise NewConnectionError(
urllib3.exceptions.NewConnectionError: <urllib3.connection.HTTPConnection object at 0x13eefca00>: Failed to establish a new connection: [Errno 61] Connection refused
During handling of the above exception, another exception occurred:
Traceback (most recent call last):
  File "/Users/visriv/Library/Python/3.9/lib/python/site-packages/requests/adapters.py", line 489, in send
    resp = conn.urlopen(
  File "/Users/visriv/Library/Python/3.9/lib/python/site-packages/urllib3/connectionpool.py", line 787, in urlopen
    retries = retries.increment(
  File "/Users/visriv/Library/Python/3.9/lib/python/site-packages/urllib3/util/retry.py", line 592, in increment
    raise MaxRetryError(_pool, url, error or ResponseError(cause))
urllib3.exceptions.MaxRetryError: HTTPConnectionPool(host='localhost', port=4500): Max retries exceeded with url: /env/test (Caused by NewConnectionError('<urllib3.connection.HTTPConnection object at 0x13eefca00>: Failed to establish a new connection: [Errno 61] Connection refused'))
During handling of the above exception, another exception occurred:
Traceback (most recent call last):
  File "/Users/visriv/Library/Python/3.9/lib/python/site-packages/visdom/__init__.py", line 756, in _send
    return self._handle_post(
  File "/Users/visriv/Library/Python/3.9/lib/python/site-packages/visdom/__init__.py", line 720, in _handle_post
    r = self.session.post(url, data=data)
  File "/Users/visriv/Library/Python/3.9/lib/python/site-packages/requests/sessions.py", line 635, in post
    return self.request("POST", url, data=data, json=json, **kwargs)
  File "/Users/visriv/Library/Python/3.9/lib/python/site-packages/requests/sessions.py", line 587, in request
    resp = self.send(prep, **send_kwargs)
  File "/Users/visriv/Library/Python/3.9/lib/python/site-packages/requests/sessions.py", line 701, in send
    r = adapter.send(request, **kwargs)
  File "/Users/visriv/Library/Python/3.9/lib/python/site-packages/requests/adapters.py", line 565, in send
    raise ConnectionError(e, request=request)
requests.exceptions.ConnectionError: HTTPConnectionPool(host='localhost', port=4500): Max retries exceeded with url: /env/test (Caused by NewConnectionError('<urllib3.connection.HTTPConnection object at 0x13eefca00>: Failed to establish a new connection: [Errno 61] Connection refused'))
[Errno 61] Connection refused
on_close() takes 1 positional argument but 3 were given
Exception in user code:
------------------------------------------------------------
1
2
3
4
5
6
7
8
9
10
11
12
13
14
15
16
17
18
19
20
21
22
23
24
25
26
27
28
29
30
31
32
33
34
35
36
37
38
39
40
41
42
43
44
45
46
47
48
49
50
51
52
53
54
55
56
57
58
59
60
61
62
63
64
65
66
67
68
69
70
71
72
73
74
75
76
77
78
79
80
81
82
83
84
85
86
87
88
89
90
91
92
93
94
95
96
97
98
99
100
[iteration 100] time: 0.03 	beta 1.00 	lambda 0.00 training ELBO: -185.8087 (-238.4984)
Exception in user code:
------------------------------------------------------------
1
2
3
4
5
6
7
8
9
10
11
12
13
14
15
16
17
18
19
20
21
22
23
24
25
26
27
28
29
30
31
32
33
34
35
Setting up a new session...
Traceback (most recent call last):
  File "/Users/visriv/Library/Python/3.9/lib/python/site-packages/urllib3/connection.py", line 174, in _new_conn
    conn = connection.create_connection(
  File "/Users/visriv/Library/Python/3.9/lib/python/site-packages/urllib3/util/connection.py", line 95, in create_connection
    raise err
  File "/Users/visriv/Library/Python/3.9/lib/python/site-packages/urllib3/util/connection.py", line 85, in create_connection
    sock.connect(sa)
ConnectionRefusedError: [Errno 61] Connection refused
During handling of the above exception, another exception occurred:
Traceback (most recent call last):
  File "/Users/visriv/Library/Python/3.9/lib/python/site-packages/urllib3/connectionpool.py", line 703, in urlopen
    httplib_response = self._make_request(
  File "/Users/visriv/Library/Python/3.9/lib/python/site-packages/urllib3/connectionpool.py", line 398, in _make_request
    conn.request(method, url, **httplib_request_kw)
  File "/Users/visriv/Library/Python/3.9/lib/python/site-packages/urllib3/connection.py", line 239, in request
    super(HTTPConnection, self).request(method, url, body=body, headers=headers)
  File "/Library/Developer/CommandLineTools/Library/Frameworks/Python3.framework/Versions/3.9/lib/python3.9/http/client.py", line 1257, in request
    self._send_request(method, url, body, headers, encode_chunked)
  File "/Library/Developer/CommandLineTools/Library/Frameworks/Python3.framework/Versions/3.9/lib/python3.9/http/client.py", line 1303, in _send_request
    self.endheaders(body, encode_chunked=encode_chunked)
  File "/Library/Developer/CommandLineTools/Library/Frameworks/Python3.framework/Versions/3.9/lib/python3.9/http/client.py", line 1252, in endheaders
    self._send_output(message_body, encode_chunked=encode_chunked)
  File "/Library/Developer/CommandLineTools/Library/Frameworks/Python3.framework/Versions/3.9/lib/python3.9/http/client.py", line 1012, in _send_output
    self.send(msg)
  File "/Library/Developer/CommandLineTools/Library/Frameworks/Python3.framework/Versions/3.9/lib/python3.9/http/client.py", line 952, in send
    self.connect()
  File "/Users/visriv/Library/Python/3.9/lib/python/site-packages/urllib3/connection.py", line 205, in connect
    conn = self._new_conn()
  File "/Users/visriv/Library/Python/3.9/lib/python/site-packages/urllib3/connection.py", line 186, in _new_conn
    raise NewConnectionError(
urllib3.exceptions.NewConnectionError: <urllib3.connection.HTTPConnection object at 0x13f3a49a0>: Failed to establish a new connection: [Errno 61] Connection refused
During handling of the above exception, another exception occurred:
Traceback (most recent call last):
  File "/Users/visriv/Library/Python/3.9/lib/python/site-packages/requests/adapters.py", line 489, in send
    resp = conn.urlopen(
  File "/Users/visriv/Library/Python/3.9/lib/python/site-packages/urllib3/connectionpool.py", line 787, in urlopen
    retries = retries.increment(
  File "/Users/visriv/Library/Python/3.9/lib/python/site-packages/urllib3/util/retry.py", line 592, in increment
    raise MaxRetryError(_pool, url, error or ResponseError(cause))
urllib3.exceptions.MaxRetryError: HTTPConnectionPool(host='localhost', port=4500): Max retries exceeded with url: /env/test (Caused by NewConnectionError('<urllib3.connection.HTTPConnection object at 0x13f3a49a0>: Failed to establish a new connection: [Errno 61] Connection refused'))
During handling of the above exception, another exception occurred:
Traceback (most recent call last):
  File "/Users/visriv/Library/Python/3.9/lib/python/site-packages/visdom/__init__.py", line 756, in _send
    return self._handle_post(
  File "/Users/visriv/Library/Python/3.9/lib/python/site-packages/visdom/__init__.py", line 720, in _handle_post
    r = self.session.post(url, data=data)
  File "/Users/visriv/Library/Python/3.9/lib/python/site-packages/requests/sessions.py", line 635, in post
    return self.request("POST", url, data=data, json=json, **kwargs)
  File "/Users/visriv/Library/Python/3.9/lib/python/site-packages/requests/sessions.py", line 587, in request
    resp = self.send(prep, **send_kwargs)
  File "/Users/visriv/Library/Python/3.9/lib/python/site-packages/requests/sessions.py", line 701, in send
    r = adapter.send(request, **kwargs)
  File "/Users/visriv/Library/Python/3.9/lib/python/site-packages/requests/adapters.py", line 565, in send
    raise ConnectionError(e, request=request)
requests.exceptions.ConnectionError: HTTPConnectionPool(host='localhost', port=4500): Max retries exceeded with url: /env/test (Caused by NewConnectionError('<urllib3.connection.HTTPConnection object at 0x13f3a49a0>: Failed to establish a new connection: [Errno 61] Connection refused'))
[Errno 61] Connection refused
on_close() takes 1 positional argument but 3 were given
36
37
38
39
40
41
42
43
44
45
46
47
48
49
50
51
52
53
54
55
56
57
58
59
60
61
62
63
64
65
66
67
68
69
70
71
72
73
74
75
76
77
78
79
80
81
82
83
84
85
86
87
88
89
90
91
92
93
94
95
96
97
98
99
100
[iteration 100] time: 0.04 	beta 1.00 	lambda 0.00 training ELBO: -184.7879 (-232.5113)
/Users/visriv/Library/Python/3.9/lib/python/site-packages/visdom/__init__.py:389: FutureWarning: The input object of type 'Tensor' is an array-like implementing one of the corresponding protocols (`__array__`, `__array_interface__` or `__array_struct__`); but not a sequence (or 0-D). In the future, this object will be coerced as if it was first converted using `np.array(obj)`. To retain the old behaviour, you have to either modify the type 'Tensor', or assign to an empty array created with `np.empty(correct_shape, dtype=object)`.
  return np.array(a)
Setting up a new session...
Traceback (most recent call last):
  File "/Users/visriv/Library/Python/3.9/lib/python/site-packages/urllib3/connection.py", line 174, in _new_conn
    conn = connection.create_connection(
  File "/Users/visriv/Library/Python/3.9/lib/python/site-packages/urllib3/util/connection.py", line 95, in create_connection
    raise err
  File "/Users/visriv/Library/Python/3.9/lib/python/site-packages/urllib3/util/connection.py", line 85, in create_connection
    sock.connect(sa)
ConnectionRefusedError: [Errno 61] Connection refused
During handling of the above exception, another exception occurred:
Traceback (most recent call last):
  File "/Users/visriv/Library/Python/3.9/lib/python/site-packages/urllib3/connectionpool.py", line 703, in urlopen
    httplib_response = self._make_request(
  File "/Users/visriv/Library/Python/3.9/lib/python/site-packages/urllib3/connectionpool.py", line 398, in _make_request
    conn.request(method, url, **httplib_request_kw)
  File "/Users/visriv/Library/Python/3.9/lib/python/site-packages/urllib3/connection.py", line 239, in request
    super(HTTPConnection, self).request(method, url, body=body, headers=headers)
  File "/Library/Developer/CommandLineTools/Library/Frameworks/Python3.framework/Versions/3.9/lib/python3.9/http/client.py", line 1257, in request
    self._send_request(method, url, body, headers, encode_chunked)
  File "/Library/Developer/CommandLineTools/Library/Frameworks/Python3.framework/Versions/3.9/lib/python3.9/http/client.py", line 1303, in _send_request
    self.endheaders(body, encode_chunked=encode_chunked)
  File "/Library/Developer/CommandLineTools/Library/Frameworks/Python3.framework/Versions/3.9/lib/python3.9/http/client.py", line 1252, in endheaders
    self._send_output(message_body, encode_chunked=encode_chunked)
  File "/Library/Developer/CommandLineTools/Library/Frameworks/Python3.framework/Versions/3.9/lib/python3.9/http/client.py", line 1012, in _send_output
    self.send(msg)
  File "/Library/Developer/CommandLineTools/Library/Frameworks/Python3.framework/Versions/3.9/lib/python3.9/http/client.py", line 952, in send
    self.connect()
  File "/Users/visriv/Library/Python/3.9/lib/python/site-packages/urllib3/connection.py", line 205, in connect
    conn = self._new_conn()
  File "/Users/visriv/Library/Python/3.9/lib/python/site-packages/urllib3/connection.py", line 186, in _new_conn
    raise NewConnectionError(
urllib3.exceptions.NewConnectionError: <urllib3.connection.HTTPConnection object at 0x12461f970>: Failed to establish a new connection: [Errno 61] Connection refused
During handling of the above exception, another exception occurred:
Traceback (most recent call last):
  File "/Users/visriv/Library/Python/3.9/lib/python/site-packages/requests/adapters.py", line 489, in send
    resp = conn.urlopen(
  File "/Users/visriv/Library/Python/3.9/lib/python/site-packages/urllib3/connectionpool.py", line 787, in urlopen
    retries = retries.increment(
  File "/Users/visriv/Library/Python/3.9/lib/python/site-packages/urllib3/util/retry.py", line 592, in increment
    raise MaxRetryError(_pool, url, error or ResponseError(cause))
urllib3.exceptions.MaxRetryError: HTTPConnectionPool(host='localhost', port=4500): Max retries exceeded with url: /env/test (Caused by NewConnectionError('<urllib3.connection.HTTPConnection object at 0x12461f970>: Failed to establish a new connection: [Errno 61] Connection refused'))
During handling of the above exception, another exception occurred:
Traceback (most recent call last):
  File "/Users/visriv/Library/Python/3.9/lib/python/site-packages/visdom/__init__.py", line 756, in _send
    return self._handle_post(
  File "/Users/visriv/Library/Python/3.9/lib/python/site-packages/visdom/__init__.py", line 720, in _handle_post
    r = self.session.post(url, data=data)
  File "/Users/visriv/Library/Python/3.9/lib/python/site-packages/requests/sessions.py", line 635, in post
    return self.request("POST", url, data=data, json=json, **kwargs)
  File "/Users/visriv/Library/Python/3.9/lib/python/site-packages/requests/sessions.py", line 587, in request
    resp = self.send(prep, **send_kwargs)
  File "/Users/visriv/Library/Python/3.9/lib/python/site-packages/requests/sessions.py", line 701, in send
    r = adapter.send(request, **kwargs)
  File "/Users/visriv/Library/Python/3.9/lib/python/site-packages/requests/adapters.py", line 565, in send
    raise ConnectionError(e, request=request)
requests.exceptions.ConnectionError: HTTPConnectionPool(host='localhost', port=4500): Max retries exceeded with url: /env/test (Caused by NewConnectionError('<urllib3.connection.HTTPConnection object at 0x12461f970>: Failed to establish a new connection: [Errno 61] Connection refused'))
[Errno 61] Connection refused
on_close() takes 1 positional argument but 3 were given
Exception in user code:
------------------------------------------------------------
1
2
3
4
5
6
7
8
9
10
11
12
13
14
15
16
17
18
19
20
21
22
23
24
25
26
27
28
29
30
31
32
33
34
35
36
37
38
39
40
41
42
43
44
45
46
47
48
49
50
51
52
53
54
55
56
57
58
59
60
61
62
63
64
65
66
67
68
69
70
71
72
73
74
75
76
77
78
79
80
81
82
83
84
85
86
87
88
89
90
91
92
93
94
95
96
97
98
99
100
[iteration 100] time: 0.03 	beta 1.00 	lambda 0.00 training ELBO: -170.9822 (-218.9923)
Setting up a new session...
Traceback (most recent call last):
  File "/Users/visriv/Library/Python/3.9/lib/python/site-packages/urllib3/connection.py", line 174, in _new_conn
    conn = connection.create_connection(
  File "/Users/visriv/Library/Python/3.9/lib/python/site-packages/urllib3/util/connection.py", line 95, in create_connection
    raise err
  File "/Users/visriv/Library/Python/3.9/lib/python/site-packages/urllib3/util/connection.py", line 85, in create_connection
    sock.connect(sa)
ConnectionRefusedError: [Errno 61] Connection refused
During handling of the above exception, another exception occurred:
Traceback (most recent call last):
  File "/Users/visriv/Library/Python/3.9/lib/python/site-packages/urllib3/connectionpool.py", line 703, in urlopen
    httplib_response = self._make_request(
  File "/Users/visriv/Library/Python/3.9/lib/python/site-packages/urllib3/connectionpool.py", line 398, in _make_request
    conn.request(method, url, **httplib_request_kw)
  File "/Users/visriv/Library/Python/3.9/lib/python/site-packages/urllib3/connection.py", line 239, in request
    super(HTTPConnection, self).request(method, url, body=body, headers=headers)
  File "/Library/Developer/CommandLineTools/Library/Frameworks/Python3.framework/Versions/3.9/lib/python3.9/http/client.py", line 1257, in request
    self._send_request(method, url, body, headers, encode_chunked)
  File "/Library/Developer/CommandLineTools/Library/Frameworks/Python3.framework/Versions/3.9/lib/python3.9/http/client.py", line 1303, in _send_request
    self.endheaders(body, encode_chunked=encode_chunked)
  File "/Library/Developer/CommandLineTools/Library/Frameworks/Python3.framework/Versions/3.9/lib/python3.9/http/client.py", line 1252, in endheaders
    self._send_output(message_body, encode_chunked=encode_chunked)
  File "/Library/Developer/CommandLineTools/Library/Frameworks/Python3.framework/Versions/3.9/lib/python3.9/http/client.py", line 1012, in _send_output
    self.send(msg)
  File "/Library/Developer/CommandLineTools/Library/Frameworks/Python3.framework/Versions/3.9/lib/python3.9/http/client.py", line 952, in send
    self.connect()
  File "/Users/visriv/Library/Python/3.9/lib/python/site-packages/urllib3/connection.py", line 205, in connect
    conn = self._new_conn()
  File "/Users/visriv/Library/Python/3.9/lib/python/site-packages/urllib3/connection.py", line 186, in _new_conn
    raise NewConnectionError(
urllib3.exceptions.NewConnectionError: <urllib3.connection.HTTPConnection object at 0x13ed91c10>: Failed to establish a new connection: [Errno 61] Connection refused
During handling of the above exception, another exception occurred:
Traceback (most recent call last):
  File "/Users/visriv/Library/Python/3.9/lib/python/site-packages/requests/adapters.py", line 489, in send
    resp = conn.urlopen(
  File "/Users/visriv/Library/Python/3.9/lib/python/site-packages/urllib3/connectionpool.py", line 787, in urlopen
    retries = retries.increment(
  File "/Users/visriv/Library/Python/3.9/lib/python/site-packages/urllib3/util/retry.py", line 592, in increment
    raise MaxRetryError(_pool, url, error or ResponseError(cause))
urllib3.exceptions.MaxRetryError: HTTPConnectionPool(host='localhost', port=4500): Max retries exceeded with url: /env/test (Caused by NewConnectionError('<urllib3.connection.HTTPConnection object at 0x13ed91c10>: Failed to establish a new connection: [Errno 61] Connection refused'))
During handling of the above exception, another exception occurred:
Traceback (most recent call last):
  File "/Users/visriv/Library/Python/3.9/lib/python/site-packages/visdom/__init__.py", line 756, in _send
    return self._handle_post(
  File "/Users/visriv/Library/Python/3.9/lib/python/site-packages/visdom/__init__.py", line 720, in _handle_post
    r = self.session.post(url, data=data)
  File "/Users/visriv/Library/Python/3.9/lib/python/site-packages/requests/sessions.py", line 635, in post
    return self.request("POST", url, data=data, json=json, **kwargs)
  File "/Users/visriv/Library/Python/3.9/lib/python/site-packages/requests/sessions.py", line 587, in request
    resp = self.send(prep, **send_kwargs)
  File "/Users/visriv/Library/Python/3.9/lib/python/site-packages/requests/sessions.py", line 701, in send
    r = adapter.send(request, **kwargs)
  File "/Users/visriv/Library/Python/3.9/lib/python/site-packages/requests/adapters.py", line 565, in send
    raise ConnectionError(e, request=request)
requests.exceptions.ConnectionError: HTTPConnectionPool(host='localhost', port=4500): Max retries exceeded with url: /env/test (Caused by NewConnectionError('<urllib3.connection.HTTPConnection object at 0x13ed91c10>: Failed to establish a new connection: [Errno 61] Connection refused'))
[Errno 61] Connection refused
on_close() takes 1 positional argument but 3 were given
Exception in user code:
------------------------------------------------------------
1
2
3
4
5
6
7
8
9
10
11
12
13
14
15
16
17
18
19
20
21
22
23
24
25
26
27
28
29
30
31
32
33
34
35
36
37
38
39
40
41
42
43
44
45
46
47
48
49
50
51
52
53
54
55
56
57
58
59
60
61
62
63
64
65
66
67
68
69
70
71
72
73
74
75
76
77
78
79
80
81
82
83
84
85
86
87
88
89
90
91
92
93
94
95
96
97
98
99
100
[iteration 100] time: 0.04 	beta 1.00 	lambda 0.00 training ELBO: -177.6421 (-221.4472)
Exception in user code:
------------------------------------------------------------
1
2
3
4
5
6
7
Setting up a new session...
Traceback (most recent call last):
  File "/Users/visriv/Library/Python/3.9/lib/python/site-packages/urllib3/connection.py", line 174, in _new_conn
    conn = connection.create_connection(
  File "/Users/visriv/Library/Python/3.9/lib/python/site-packages/urllib3/util/connection.py", line 95, in create_connection
    raise err
  File "/Users/visriv/Library/Python/3.9/lib/python/site-packages/urllib3/util/connection.py", line 85, in create_connection
    sock.connect(sa)
ConnectionRefusedError: [Errno 61] Connection refused
During handling of the above exception, another exception occurred:
Traceback (most recent call last):
  File "/Users/visriv/Library/Python/3.9/lib/python/site-packages/urllib3/connectionpool.py", line 703, in urlopen
    httplib_response = self._make_request(
  File "/Users/visriv/Library/Python/3.9/lib/python/site-packages/urllib3/connectionpool.py", line 398, in _make_request
    conn.request(method, url, **httplib_request_kw)
  File "/Users/visriv/Library/Python/3.9/lib/python/site-packages/urllib3/connection.py", line 239, in request
    super(HTTPConnection, self).request(method, url, body=body, headers=headers)
  File "/Library/Developer/CommandLineTools/Library/Frameworks/Python3.framework/Versions/3.9/lib/python3.9/http/client.py", line 1257, in request
    self._send_request(method, url, body, headers, encode_chunked)
  File "/Library/Developer/CommandLineTools/Library/Frameworks/Python3.framework/Versions/3.9/lib/python3.9/http/client.py", line 1303, in _send_request
    self.endheaders(body, encode_chunked=encode_chunked)
  File "/Library/Developer/CommandLineTools/Library/Frameworks/Python3.framework/Versions/3.9/lib/python3.9/http/client.py", line 1252, in endheaders
    self._send_output(message_body, encode_chunked=encode_chunked)
  File "/Library/Developer/CommandLineTools/Library/Frameworks/Python3.framework/Versions/3.9/lib/python3.9/http/client.py", line 1012, in _send_output
    self.send(msg)
  File "/Library/Developer/CommandLineTools/Library/Frameworks/Python3.framework/Versions/3.9/lib/python3.9/http/client.py", line 952, in send
    self.connect()
  File "/Users/visriv/Library/Python/3.9/lib/python/site-packages/urllib3/connection.py", line 205, in connect
    conn = self._new_conn()
  File "/Users/visriv/Library/Python/3.9/lib/python/site-packages/urllib3/connection.py", line 186, in _new_conn
    raise NewConnectionError(
urllib3.exceptions.NewConnectionError: <urllib3.connection.HTTPConnection object at 0x1241ef520>: Failed to establish a new connection: [Errno 61] Connection refused
During handling of the above exception, another exception occurred:
Traceback (most recent call last):
  File "/Users/visriv/Library/Python/3.9/lib/python/site-packages/requests/adapters.py", line 489, in send
    resp = conn.urlopen(
  File "/Users/visriv/Library/Python/3.9/lib/python/site-packages/urllib3/connectionpool.py", line 787, in urlopen
    retries = retries.increment(
  File "/Users/visriv/Library/Python/3.9/lib/python/site-packages/urllib3/util/retry.py", line 592, in increment
    raise MaxRetryError(_pool, url, error or ResponseError(cause))
urllib3.exceptions.MaxRetryError: HTTPConnectionPool(host='localhost', port=4500): Max retries exceeded with url: /env/test (Caused by NewConnectionError('<urllib3.connection.HTTPConnection object at 0x1241ef520>: Failed to establish a new connection: [Errno 61] Connection refused'))
During handling of the above exception, another exception occurred:
Traceback (most recent call last):
  File "/Users/visriv/Library/Python/3.9/lib/python/site-packages/visdom/__init__.py", line 756, in _send
    return self._handle_post(
  File "/Users/visriv/Library/Python/3.9/lib/python/site-packages/visdom/__init__.py", line 720, in _handle_post
    r = self.session.post(url, data=data)
  File "/Users/visriv/Library/Python/3.9/lib/python/site-packages/requests/sessions.py", line 635, in post
    return self.request("POST", url, data=data, json=json, **kwargs)
  File "/Users/visriv/Library/Python/3.9/lib/python/site-packages/requests/sessions.py", line 587, in request
    resp = self.send(prep, **send_kwargs)
  File "/Users/visriv/Library/Python/3.9/lib/python/site-packages/requests/sessions.py", line 701, in send
    r = adapter.send(request, **kwargs)
  File "/Users/visriv/Library/Python/3.9/lib/python/site-packages/requests/adapters.py", line 565, in send
    raise ConnectionError(e, request=request)
requests.exceptions.ConnectionError: HTTPConnectionPool(host='localhost', port=4500): Max retries exceeded with url: /env/test (Caused by NewConnectionError('<urllib3.connection.HTTPConnection object at 0x1241ef520>: Failed to establish a new connection: [Errno 61] Connection refused'))
[Errno 61] Connection refused
on_close() takes 1 positional argument but 3 were given
8
9
10
11
12
13
14
15
16
17
18
19
20
21
22
23
24
25
26
27
28
29
30
31
32
33
34
35
36
37
38
39
40
41
42
43
44
45
46
47
48
49
50
51
52
53
54
55
56
57
58
59
60
61
62
63
64
65
66
67
68
69
70
71
72
73
74
75
76
77
78
79
80
81
82
83
84
85
86
87
88
89
90
91
92
93
94
95
96
97
98
99
100
[iteration 100] time: 0.04 	beta 1.00 	lambda 0.00 training ELBO: -178.3976 (-227.2281)
Setting up a new session...
Traceback (most recent call last):
  File "/Users/visriv/Library/Python/3.9/lib/python/site-packages/urllib3/connection.py", line 174, in _new_conn
    conn = connection.create_connection(
  File "/Users/visriv/Library/Python/3.9/lib/python/site-packages/urllib3/util/connection.py", line 95, in create_connection
    raise err
  File "/Users/visriv/Library/Python/3.9/lib/python/site-packages/urllib3/util/connection.py", line 85, in create_connection
    sock.connect(sa)
ConnectionRefusedError: [Errno 61] Connection refused
During handling of the above exception, another exception occurred:
Traceback (most recent call last):
  File "/Users/visriv/Library/Python/3.9/lib/python/site-packages/urllib3/connectionpool.py", line 703, in urlopen
    httplib_response = self._make_request(
  File "/Users/visriv/Library/Python/3.9/lib/python/site-packages/urllib3/connectionpool.py", line 398, in _make_request
    conn.request(method, url, **httplib_request_kw)
  File "/Users/visriv/Library/Python/3.9/lib/python/site-packages/urllib3/connection.py", line 239, in request
    super(HTTPConnection, self).request(method, url, body=body, headers=headers)
  File "/Library/Developer/CommandLineTools/Library/Frameworks/Python3.framework/Versions/3.9/lib/python3.9/http/client.py", line 1257, in request
    self._send_request(method, url, body, headers, encode_chunked)
  File "/Library/Developer/CommandLineTools/Library/Frameworks/Python3.framework/Versions/3.9/lib/python3.9/http/client.py", line 1303, in _send_request
    self.endheaders(body, encode_chunked=encode_chunked)
  File "/Library/Developer/CommandLineTools/Library/Frameworks/Python3.framework/Versions/3.9/lib/python3.9/http/client.py", line 1252, in endheaders
    self._send_output(message_body, encode_chunked=encode_chunked)
  File "/Library/Developer/CommandLineTools/Library/Frameworks/Python3.framework/Versions/3.9/lib/python3.9/http/client.py", line 1012, in _send_output
    self.send(msg)
  File "/Library/Developer/CommandLineTools/Library/Frameworks/Python3.framework/Versions/3.9/lib/python3.9/http/client.py", line 952, in send
    self.connect()
  File "/Users/visriv/Library/Python/3.9/lib/python/site-packages/urllib3/connection.py", line 205, in connect
    conn = self._new_conn()
  File "/Users/visriv/Library/Python/3.9/lib/python/site-packages/urllib3/connection.py", line 186, in _new_conn
    raise NewConnectionError(
urllib3.exceptions.NewConnectionError: <urllib3.connection.HTTPConnection object at 0x124270430>: Failed to establish a new connection: [Errno 61] Connection refused
During handling of the above exception, another exception occurred:
Traceback (most recent call last):
  File "/Users/visriv/Library/Python/3.9/lib/python/site-packages/requests/adapters.py", line 489, in send
    resp = conn.urlopen(
  File "/Users/visriv/Library/Python/3.9/lib/python/site-packages/urllib3/connectionpool.py", line 787, in urlopen
    retries = retries.increment(
  File "/Users/visriv/Library/Python/3.9/lib/python/site-packages/urllib3/util/retry.py", line 592, in increment
    raise MaxRetryError(_pool, url, error or ResponseError(cause))
urllib3.exceptions.MaxRetryError: HTTPConnectionPool(host='localhost', port=4500): Max retries exceeded with url: /env/test (Caused by NewConnectionError('<urllib3.connection.HTTPConnection object at 0x124270430>: Failed to establish a new connection: [Errno 61] Connection refused'))
During handling of the above exception, another exception occurred:
Traceback (most recent call last):
  File "/Users/visriv/Library/Python/3.9/lib/python/site-packages/visdom/__init__.py", line 756, in _send
    return self._handle_post(
  File "/Users/visriv/Library/Python/3.9/lib/python/site-packages/visdom/__init__.py", line 720, in _handle_post
    r = self.session.post(url, data=data)
  File "/Users/visriv/Library/Python/3.9/lib/python/site-packages/requests/sessions.py", line 635, in post
    return self.request("POST", url, data=data, json=json, **kwargs)
  File "/Users/visriv/Library/Python/3.9/lib/python/site-packages/requests/sessions.py", line 587, in request
    resp = self.send(prep, **send_kwargs)
  File "/Users/visriv/Library/Python/3.9/lib/python/site-packages/requests/sessions.py", line 701, in send
    r = adapter.send(request, **kwargs)
  File "/Users/visriv/Library/Python/3.9/lib/python/site-packages/requests/adapters.py", line 565, in send
    raise ConnectionError(e, request=request)
requests.exceptions.ConnectionError: HTTPConnectionPool(host='localhost', port=4500): Max retries exceeded with url: /env/test (Caused by NewConnectionError('<urllib3.connection.HTTPConnection object at 0x124270430>: Failed to establish a new connection: [Errno 61] Connection refused'))
[Errno 61] Connection refused
on_close() takes 1 positional argument but 3 were given
Exception in user code:
------------------------------------------------------------
1
2
3
4
5
6
7
8
9
10
11
12
13
14
15
16
17
18
19
20
21
22
23
24
25
26
27
28
29
30
31
32
33
34
35
36
37
38
39
40
41
42
43
44
45
46
47
48
49
50
51
52
53
54
55
56
57
58
59
60
61
62
63
64
/Users/visriv/Documents/Git/beta-tcvae/lib/utils_plot.py:40: UserWarning: volatile was removed and now has no effect. Use `with torch.no_grad():` instead.
  vec = Variable(torch.zeros(z_dim)).view(1, z_dim).expand(7, z_dim).contiguous().type_as(zs)
65
66
67
68
69
70
71
72
73
74
75
76
77
78
79
80
81
82
83
84
85
86
87
88
89
90
91
92
93
94
95
96
97
98
99
100
[iteration 100] time: 0.04 	beta 1.00 	lambda 0.00 training ELBO: -191.0155 (-237.1276)
Exception in user code:
------------------------------------------------------------
1
2
3
4
5
6
7
8
9
10
11
12
13
14
15
16
17
18
19
20
21
22
23
Setting up a new session...
Traceback (most recent call last):
  File "/Users/visriv/Library/Python/3.9/lib/python/site-packages/urllib3/connection.py", line 174, in _new_conn
    conn = connection.create_connection(
  File "/Users/visriv/Library/Python/3.9/lib/python/site-packages/urllib3/util/connection.py", line 95, in create_connection
    raise err
  File "/Users/visriv/Library/Python/3.9/lib/python/site-packages/urllib3/util/connection.py", line 85, in create_connection
    sock.connect(sa)
ConnectionRefusedError: [Errno 61] Connection refused
During handling of the above exception, another exception occurred:
Traceback (most recent call last):
  File "/Users/visriv/Library/Python/3.9/lib/python/site-packages/urllib3/connectionpool.py", line 703, in urlopen
    httplib_response = self._make_request(
  File "/Users/visriv/Library/Python/3.9/lib/python/site-packages/urllib3/connectionpool.py", line 398, in _make_request
    conn.request(method, url, **httplib_request_kw)
  File "/Users/visriv/Library/Python/3.9/lib/python/site-packages/urllib3/connection.py", line 239, in request
    super(HTTPConnection, self).request(method, url, body=body, headers=headers)
  File "/Library/Developer/CommandLineTools/Library/Frameworks/Python3.framework/Versions/3.9/lib/python3.9/http/client.py", line 1257, in request
    self._send_request(method, url, body, headers, encode_chunked)
  File "/Library/Developer/CommandLineTools/Library/Frameworks/Python3.framework/Versions/3.9/lib/python3.9/http/client.py", line 1303, in _send_request
    self.endheaders(body, encode_chunked=encode_chunked)
  File "/Library/Developer/CommandLineTools/Library/Frameworks/Python3.framework/Versions/3.9/lib/python3.9/http/client.py", line 1252, in endheaders
    self._send_output(message_body, encode_chunked=encode_chunked)
  File "/Library/Developer/CommandLineTools/Library/Frameworks/Python3.framework/Versions/3.9/lib/python3.9/http/client.py", line 1012, in _send_output
    self.send(msg)
  File "/Library/Developer/CommandLineTools/Library/Frameworks/Python3.framework/Versions/3.9/lib/python3.9/http/client.py", line 952, in send
    self.connect()
  File "/Users/visriv/Library/Python/3.9/lib/python/site-packages/urllib3/connection.py", line 205, in connect
    conn = self._new_conn()
  File "/Users/visriv/Library/Python/3.9/lib/python/site-packages/urllib3/connection.py", line 186, in _new_conn
    raise NewConnectionError(
urllib3.exceptions.NewConnectionError: <urllib3.connection.HTTPConnection object at 0x1242ff4f0>: Failed to establish a new connection: [Errno 61] Connection refused
During handling of the above exception, another exception occurred:
Traceback (most recent call last):
  File "/Users/visriv/Library/Python/3.9/lib/python/site-packages/requests/adapters.py", line 489, in send
    resp = conn.urlopen(
  File "/Users/visriv/Library/Python/3.9/lib/python/site-packages/urllib3/connectionpool.py", line 787, in urlopen
    retries = retries.increment(
  File "/Users/visriv/Library/Python/3.9/lib/python/site-packages/urllib3/util/retry.py", line 592, in increment
    raise MaxRetryError(_pool, url, error or ResponseError(cause))
urllib3.exceptions.MaxRetryError: HTTPConnectionPool(host='localhost', port=4500): Max retries exceeded with url: /env/test (Caused by NewConnectionError('<urllib3.connection.HTTPConnection object at 0x1242ff4f0>: Failed to establish a new connection: [Errno 61] Connection refused'))
During handling of the above exception, another exception occurred:
Traceback (most recent call last):
  File "/Users/visriv/Library/Python/3.9/lib/python/site-packages/visdom/__init__.py", line 756, in _send
    return self._handle_post(
  File "/Users/visriv/Library/Python/3.9/lib/python/site-packages/visdom/__init__.py", line 720, in _handle_post
    r = self.session.post(url, data=data)
  File "/Users/visriv/Library/Python/3.9/lib/python/site-packages/requests/sessions.py", line 635, in post
    return self.request("POST", url, data=data, json=json, **kwargs)
  File "/Users/visriv/Library/Python/3.9/lib/python/site-packages/requests/sessions.py", line 587, in request
    resp = self.send(prep, **send_kwargs)
  File "/Users/visriv/Library/Python/3.9/lib/python/site-packages/requests/sessions.py", line 701, in send
    r = adapter.send(request, **kwargs)
  File "/Users/visriv/Library/Python/3.9/lib/python/site-packages/requests/adapters.py", line 565, in send
    raise ConnectionError(e, request=request)
requests.exceptions.ConnectionError: HTTPConnectionPool(host='localhost', port=4500): Max retries exceeded with url: /env/test (Caused by NewConnectionError('<urllib3.connection.HTTPConnection object at 0x1242ff4f0>: Failed to establish a new connection: [Errno 61] Connection refused'))
[Errno 61] Connection refused
on_close() takes 1 positional argument but 3 were given
24
25
26
27
28
29
30
31
32
33
34
35
36
37
38
39
40
41
42
43
44
45
46
47
48
49
50
51
52
53
54
55
56
57
58
59
60
61
62
63
64
65
66
67
68
69
70
/Users/visriv/Documents/Git/beta-tcvae/lib/utils_plot.py:41: UserWarning: volatile was removed and now has no effect. Use `with torch.no_grad():` instead.
  for i in range(z_dim):
71
72
73
74
75
76
77
78
79
80
81
82
83
84
85
86
87
88
89
90
91
92
93
94
95
96
97
98
99
100
[iteration 100] time: 0.04 	beta 1.00 	lambda 0.00 training ELBO: -189.7982 (-219.4627)
Exception in user code:
------------------------------------------------------------
1
2
3
4
5
6
7
8
9
10
11
12
13
14
15
16
17
18
19
20
21
22
23
24
25
26
27
28
Setting up a new session...
Traceback (most recent call last):
  File "/Users/visriv/Library/Python/3.9/lib/python/site-packages/urllib3/connection.py", line 174, in _new_conn
    conn = connection.create_connection(
  File "/Users/visriv/Library/Python/3.9/lib/python/site-packages/urllib3/util/connection.py", line 95, in create_connection
    raise err
  File "/Users/visriv/Library/Python/3.9/lib/python/site-packages/urllib3/util/connection.py", line 85, in create_connection
    sock.connect(sa)
ConnectionRefusedError: [Errno 61] Connection refused
During handling of the above exception, another exception occurred:
Traceback (most recent call last):
  File "/Users/visriv/Library/Python/3.9/lib/python/site-packages/urllib3/connectionpool.py", line 703, in urlopen
    httplib_response = self._make_request(
  File "/Users/visriv/Library/Python/3.9/lib/python/site-packages/urllib3/connectionpool.py", line 398, in _make_request
    conn.request(method, url, **httplib_request_kw)
  File "/Users/visriv/Library/Python/3.9/lib/python/site-packages/urllib3/connection.py", line 239, in request
    super(HTTPConnection, self).request(method, url, body=body, headers=headers)
  File "/Library/Developer/CommandLineTools/Library/Frameworks/Python3.framework/Versions/3.9/lib/python3.9/http/client.py", line 1257, in request
    self._send_request(method, url, body, headers, encode_chunked)
  File "/Library/Developer/CommandLineTools/Library/Frameworks/Python3.framework/Versions/3.9/lib/python3.9/http/client.py", line 1303, in _send_request
    self.endheaders(body, encode_chunked=encode_chunked)
  File "/Library/Developer/CommandLineTools/Library/Frameworks/Python3.framework/Versions/3.9/lib/python3.9/http/client.py", line 1252, in endheaders
    self._send_output(message_body, encode_chunked=encode_chunked)
  File "/Library/Developer/CommandLineTools/Library/Frameworks/Python3.framework/Versions/3.9/lib/python3.9/http/client.py", line 1012, in _send_output
    self.send(msg)
  File "/Library/Developer/CommandLineTools/Library/Frameworks/Python3.framework/Versions/3.9/lib/python3.9/http/client.py", line 952, in send
    self.connect()
  File "/Users/visriv/Library/Python/3.9/lib/python/site-packages/urllib3/connection.py", line 205, in connect
    conn = self._new_conn()
  File "/Users/visriv/Library/Python/3.9/lib/python/site-packages/urllib3/connection.py", line 186, in _new_conn
    raise NewConnectionError(
urllib3.exceptions.NewConnectionError: <urllib3.connection.HTTPConnection object at 0x123d040a0>: Failed to establish a new connection: [Errno 61] Connection refused
During handling of the above exception, another exception occurred:
Traceback (most recent call last):
  File "/Users/visriv/Library/Python/3.9/lib/python/site-packages/requests/adapters.py", line 489, in send
    resp = conn.urlopen(
  File "/Users/visriv/Library/Python/3.9/lib/python/site-packages/urllib3/connectionpool.py", line 787, in urlopen
    retries = retries.increment(
  File "/Users/visriv/Library/Python/3.9/lib/python/site-packages/urllib3/util/retry.py", line 592, in increment
    raise MaxRetryError(_pool, url, error or ResponseError(cause))
urllib3.exceptions.MaxRetryError: HTTPConnectionPool(host='localhost', port=4500): Max retries exceeded with url: /env/test (Caused by NewConnectionError('<urllib3.connection.HTTPConnection object at 0x123d040a0>: Failed to establish a new connection: [Errno 61] Connection refused'))
During handling of the above exception, another exception occurred:
Traceback (most recent call last):
  File "/Users/visriv/Library/Python/3.9/lib/python/site-packages/visdom/__init__.py", line 756, in _send
    return self._handle_post(
  File "/Users/visriv/Library/Python/3.9/lib/python/site-packages/visdom/__init__.py", line 720, in _handle_post
    r = self.session.post(url, data=data)
  File "/Users/visriv/Library/Python/3.9/lib/python/site-packages/requests/sessions.py", line 635, in post
    return self.request("POST", url, data=data, json=json, **kwargs)
  File "/Users/visriv/Library/Python/3.9/lib/python/site-packages/requests/sessions.py", line 587, in request
    resp = self.send(prep, **send_kwargs)
  File "/Users/visriv/Library/Python/3.9/lib/python/site-packages/requests/sessions.py", line 701, in send
    r = adapter.send(request, **kwargs)
  File "/Users/visriv/Library/Python/3.9/lib/python/site-packages/requests/adapters.py", line 565, in send
    raise ConnectionError(e, request=request)
requests.exceptions.ConnectionError: HTTPConnectionPool(host='localhost', port=4500): Max retries exceeded with url: /env/test (Caused by NewConnectionError('<urllib3.connection.HTTPConnection object at 0x123d040a0>: Failed to establish a new connection: [Errno 61] Connection refused'))
[Errno 61] Connection refused
on_close() takes 1 positional argument but 3 were given
29
30
31
32
33
34
35
36
37
38
39
40
41
42
43
44
45
46
47
48
49
50
51
52
53
54
55
56
57
58
59
60
61
62
63
64
65
66
67
68
69
70
71
72
73
74
75
76
77
78
79
80
81
82
83
84
85
86
87
88
89
90
91
92
93
94
95
96
97
98
99
100
[iteration 100] time: 0.03 	beta 1.00 	lambda 0.00 training ELBO: -186.7810 (-215.4127)
Exception in user code:
------------------------------------------------------------
1
2
3
4
5
6
7
8
9
10
11
12
13
14
15
16
17
18
19
20
21
22
23
24
25
26
27
28
Setting up a new session...
Traceback (most recent call last):
  File "/Users/visriv/Library/Python/3.9/lib/python/site-packages/urllib3/connection.py", line 174, in _new_conn
    conn = connection.create_connection(
  File "/Users/visriv/Library/Python/3.9/lib/python/site-packages/urllib3/util/connection.py", line 95, in create_connection
    raise err
  File "/Users/visriv/Library/Python/3.9/lib/python/site-packages/urllib3/util/connection.py", line 85, in create_connection
    sock.connect(sa)
ConnectionRefusedError: [Errno 61] Connection refused
During handling of the above exception, another exception occurred:
Traceback (most recent call last):
  File "/Users/visriv/Library/Python/3.9/lib/python/site-packages/urllib3/connectionpool.py", line 703, in urlopen
    httplib_response = self._make_request(
  File "/Users/visriv/Library/Python/3.9/lib/python/site-packages/urllib3/connectionpool.py", line 398, in _make_request
    conn.request(method, url, **httplib_request_kw)
  File "/Users/visriv/Library/Python/3.9/lib/python/site-packages/urllib3/connection.py", line 239, in request
    super(HTTPConnection, self).request(method, url, body=body, headers=headers)
  File "/Library/Developer/CommandLineTools/Library/Frameworks/Python3.framework/Versions/3.9/lib/python3.9/http/client.py", line 1257, in request
    self._send_request(method, url, body, headers, encode_chunked)
  File "/Library/Developer/CommandLineTools/Library/Frameworks/Python3.framework/Versions/3.9/lib/python3.9/http/client.py", line 1303, in _send_request
    self.endheaders(body, encode_chunked=encode_chunked)
  File "/Library/Developer/CommandLineTools/Library/Frameworks/Python3.framework/Versions/3.9/lib/python3.9/http/client.py", line 1252, in endheaders
    self._send_output(message_body, encode_chunked=encode_chunked)
  File "/Library/Developer/CommandLineTools/Library/Frameworks/Python3.framework/Versions/3.9/lib/python3.9/http/client.py", line 1012, in _send_output
    self.send(msg)
  File "/Library/Developer/CommandLineTools/Library/Frameworks/Python3.framework/Versions/3.9/lib/python3.9/http/client.py", line 952, in send
    self.connect()
  File "/Users/visriv/Library/Python/3.9/lib/python/site-packages/urllib3/connection.py", line 205, in connect
    conn = self._new_conn()
  File "/Users/visriv/Library/Python/3.9/lib/python/site-packages/urllib3/connection.py", line 186, in _new_conn
    raise NewConnectionError(
urllib3.exceptions.NewConnectionError: <urllib3.connection.HTTPConnection object at 0x124118640>: Failed to establish a new connection: [Errno 61] Connection refused
During handling of the above exception, another exception occurred:
Traceback (most recent call last):
  File "/Users/visriv/Library/Python/3.9/lib/python/site-packages/requests/adapters.py", line 489, in send
    resp = conn.urlopen(
  File "/Users/visriv/Library/Python/3.9/lib/python/site-packages/urllib3/connectionpool.py", line 787, in urlopen
    retries = retries.increment(
  File "/Users/visriv/Library/Python/3.9/lib/python/site-packages/urllib3/util/retry.py", line 592, in increment
    raise MaxRetryError(_pool, url, error or ResponseError(cause))
urllib3.exceptions.MaxRetryError: HTTPConnectionPool(host='localhost', port=4500): Max retries exceeded with url: /env/test (Caused by NewConnectionError('<urllib3.connection.HTTPConnection object at 0x124118640>: Failed to establish a new connection: [Errno 61] Connection refused'))
During handling of the above exception, another exception occurred:
Traceback (most recent call last):
  File "/Users/visriv/Library/Python/3.9/lib/python/site-packages/visdom/__init__.py", line 756, in _send
    return self._handle_post(
  File "/Users/visriv/Library/Python/3.9/lib/python/site-packages/visdom/__init__.py", line 720, in _handle_post
    r = self.session.post(url, data=data)
  File "/Users/visriv/Library/Python/3.9/lib/python/site-packages/requests/sessions.py", line 635, in post
    return self.request("POST", url, data=data, json=json, **kwargs)
  File "/Users/visriv/Library/Python/3.9/lib/python/site-packages/requests/sessions.py", line 587, in request
    resp = self.send(prep, **send_kwargs)
  File "/Users/visriv/Library/Python/3.9/lib/python/site-packages/requests/sessions.py", line 701, in send
    r = adapter.send(request, **kwargs)
  File "/Users/visriv/Library/Python/3.9/lib/python/site-packages/requests/adapters.py", line 565, in send
    raise ConnectionError(e, request=request)
requests.exceptions.ConnectionError: HTTPConnectionPool(host='localhost', port=4500): Max retries exceeded with url: /env/test (Caused by NewConnectionError('<urllib3.connection.HTTPConnection object at 0x124118640>: Failed to establish a new connection: [Errno 61] Connection refused'))
[Errno 61] Connection refused
on_close() takes 1 positional argument but 3 were given
29
30
31
32
33
34
35
36
37
38
39
40
41
42
43
44
45
46
47
48
49
50
51
52
53
54
55
56
57
58
59
60
61
62
63
64
65
66
67
68
69
70
71
72
73
74
75
Traceback (most recent call last):
  File "/Users/visriv/Library/Python/3.9/lib/python/site-packages/urllib3/connection.py", line 174, in _new_conn
    conn = connection.create_connection(
  File "/Users/visriv/Library/Python/3.9/lib/python/site-packages/urllib3/util/connection.py", line 95, in create_connection
    raise err
  File "/Users/visriv/Library/Python/3.9/lib/python/site-packages/urllib3/util/connection.py", line 85, in create_connection
    sock.connect(sa)
ConnectionRefusedError: [Errno 61] Connection refused
During handling of the above exception, another exception occurred:
Traceback (most recent call last):
  File "/Users/visriv/Library/Python/3.9/lib/python/site-packages/urllib3/connectionpool.py", line 703, in urlopen
    httplib_response = self._make_request(
  File "/Users/visriv/Library/Python/3.9/lib/python/site-packages/urllib3/connectionpool.py", line 398, in _make_request
    conn.request(method, url, **httplib_request_kw)
  File "/Users/visriv/Library/Python/3.9/lib/python/site-packages/urllib3/connection.py", line 239, in request
    super(HTTPConnection, self).request(method, url, body=body, headers=headers)
  File "/Library/Developer/CommandLineTools/Library/Frameworks/Python3.framework/Versions/3.9/lib/python3.9/http/client.py", line 1257, in request
    self._send_request(method, url, body, headers, encode_chunked)
  File "/Library/Developer/CommandLineTools/Library/Frameworks/Python3.framework/Versions/3.9/lib/python3.9/http/client.py", line 1303, in _send_request
    self.endheaders(body, encode_chunked=encode_chunked)
  File "/Library/Developer/CommandLineTools/Library/Frameworks/Python3.framework/Versions/3.9/lib/python3.9/http/client.py", line 1252, in endheaders
    self._send_output(message_body, encode_chunked=encode_chunked)
  File "/Library/Developer/CommandLineTools/Library/Frameworks/Python3.framework/Versions/3.9/lib/python3.9/http/client.py", line 1012, in _send_output
    self.send(msg)
  File "/Library/Developer/CommandLineTools/Library/Frameworks/Python3.framework/Versions/3.9/lib/python3.9/http/client.py", line 952, in send
    self.connect()
  File "/Users/visriv/Library/Python/3.9/lib/python/site-packages/urllib3/connection.py", line 205, in connect
    conn = self._new_conn()
  File "/Users/visriv/Library/Python/3.9/lib/python/site-packages/urllib3/connection.py", line 186, in _new_conn
    raise NewConnectionError(
urllib3.exceptions.NewConnectionError: <urllib3.connection.HTTPConnection object at 0x13f777580>: Failed to establish a new connection: [Errno 61] Connection refused
During handling of the above exception, another exception occurred:
Traceback (most recent call last):
  File "/Users/visriv/Library/Python/3.9/lib/python/site-packages/requests/adapters.py", line 489, in send
    resp = conn.urlopen(
  File "/Users/visriv/Library/Python/3.9/lib/python/site-packages/urllib3/connectionpool.py", line 787, in urlopen
    retries = retries.increment(
  File "/Users/visriv/Library/Python/3.9/lib/python/site-packages/urllib3/util/retry.py", line 592, in increment
    raise MaxRetryError(_pool, url, error or ResponseError(cause))
urllib3.exceptions.MaxRetryError: HTTPConnectionPool(host='localhost', port=4500): Max retries exceeded with url: /events (Caused by NewConnectionError('<urllib3.connection.HTTPConnection object at 0x13f777580>: Failed to establish a new connection: [Errno 61] Connection refused'))
During handling of the above exception, another exception occurred:
Traceback (most recent call last):
  File "/Users/visriv/Library/Python/3.9/lib/python/site-packages/visdom/__init__.py", line 756, in _send
    return self._handle_post(
  File "/Users/visriv/Library/Python/3.9/lib/python/site-packages/visdom/__init__.py", line 720, in _handle_post
    r = self.session.post(url, data=data)
  File "/Users/visriv/Library/Python/3.9/lib/python/site-packages/requests/sessions.py", line 635, in post
    return self.request("POST", url, data=data, json=json, **kwargs)
  File "/Users/visriv/Library/Python/3.9/lib/python/site-packages/requests/sessions.py", line 587, in request
    resp = self.send(prep, **send_kwargs)
  File "/Users/visriv/Library/Python/3.9/lib/python/site-packages/requests/sessions.py", line 701, in send
    r = adapter.send(request, **kwargs)
  File "/Users/visriv/Library/Python/3.9/lib/python/site-packages/requests/adapters.py", line 565, in send
    raise ConnectionError(e, request=request)
requests.exceptions.ConnectionError: HTTPConnectionPool(host='localhost', port=4500): Max retries exceeded with url: /events (Caused by NewConnectionError('<urllib3.connection.HTTPConnection object at 0x13f777580>: Failed to establish a new connection: [Errno 61] Connection refused'))
76
77
78
79
80
81
82
83
84
85
86
87
88
89
90
91
92
93
94
95
96
97
98
99
100
[iteration 100] time: 0.04 	beta 1.00 	lambda 0.00 training ELBO: -185.1738 (-236.6222)
Exception in user code:
------------------------------------------------------------
Active units: 0,1,2,3,4,5,6,7,8,9
Number of active units: 10/10
101
102
103
104
105
106
107
108
109
110
111
112
113
114
115
116
117
118
119
120
121
122
123
124
125
126
127
128
129
130
131
132
133
134
135
136
137
138
139
140
141
142
143
144
145
146
147
148
149
150
151
152
153
154
155
156
157
158
159
160
161
162
163
164
165
166
167
168
169
170
Traceback (most recent call last):
  File "/Users/visriv/Library/Python/3.9/lib/python/site-packages/urllib3/connection.py", line 174, in _new_conn
    conn = connection.create_connection(
  File "/Users/visriv/Library/Python/3.9/lib/python/site-packages/urllib3/util/connection.py", line 95, in create_connection
    raise err
  File "/Users/visriv/Library/Python/3.9/lib/python/site-packages/urllib3/util/connection.py", line 85, in create_connection
    sock.connect(sa)
ConnectionRefusedError: [Errno 61] Connection refused
During handling of the above exception, another exception occurred:
Traceback (most recent call last):
  File "/Users/visriv/Library/Python/3.9/lib/python/site-packages/urllib3/connectionpool.py", line 703, in urlopen
    httplib_response = self._make_request(
  File "/Users/visriv/Library/Python/3.9/lib/python/site-packages/urllib3/connectionpool.py", line 398, in _make_request
    conn.request(method, url, **httplib_request_kw)
  File "/Users/visriv/Library/Python/3.9/lib/python/site-packages/urllib3/connection.py", line 239, in request
    super(HTTPConnection, self).request(method, url, body=body, headers=headers)
  File "/Library/Developer/CommandLineTools/Library/Frameworks/Python3.framework/Versions/3.9/lib/python3.9/http/client.py", line 1257, in request
    self._send_request(method, url, body, headers, encode_chunked)
  File "/Library/Developer/CommandLineTools/Library/Frameworks/Python3.framework/Versions/3.9/lib/python3.9/http/client.py", line 1303, in _send_request
    self.endheaders(body, encode_chunked=encode_chunked)
  File "/Library/Developer/CommandLineTools/Library/Frameworks/Python3.framework/Versions/3.9/lib/python3.9/http/client.py", line 1252, in endheaders
    self._send_output(message_body, encode_chunked=encode_chunked)
  File "/Library/Developer/CommandLineTools/Library/Frameworks/Python3.framework/Versions/3.9/lib/python3.9/http/client.py", line 1012, in _send_output
    self.send(msg)
  File "/Library/Developer/CommandLineTools/Library/Frameworks/Python3.framework/Versions/3.9/lib/python3.9/http/client.py", line 952, in send
    self.connect()
  File "/Users/visriv/Library/Python/3.9/lib/python/site-packages/urllib3/connection.py", line 205, in connect
    conn = self._new_conn()
  File "/Users/visriv/Library/Python/3.9/lib/python/site-packages/urllib3/connection.py", line 186, in _new_conn
    raise NewConnectionError(
urllib3.exceptions.NewConnectionError: <urllib3.connection.HTTPConnection object at 0x13fa39c10>: Failed to establish a new connection: [Errno 61] Connection refused
During handling of the above exception, another exception occurred:
Traceback (most recent call last):
  File "/Users/visriv/Library/Python/3.9/lib/python/site-packages/requests/adapters.py", line 489, in send
    resp = conn.urlopen(
  File "/Users/visriv/Library/Python/3.9/lib/python/site-packages/urllib3/connectionpool.py", line 787, in urlopen
    retries = retries.increment(
  File "/Users/visriv/Library/Python/3.9/lib/python/site-packages/urllib3/util/retry.py", line 592, in increment
    raise MaxRetryError(_pool, url, error or ResponseError(cause))
urllib3.exceptions.MaxRetryError: HTTPConnectionPool(host='localhost', port=4500): Max retries exceeded with url: /events (Caused by NewConnectionError('<urllib3.connection.HTTPConnection object at 0x13fa39c10>: Failed to establish a new connection: [Errno 61] Connection refused'))
During handling of the above exception, another exception occurred:
Traceback (most recent call last):
  File "/Users/visriv/Library/Python/3.9/lib/python/site-packages/visdom/__init__.py", line 756, in _send
    return self._handle_post(
  File "/Users/visriv/Library/Python/3.9/lib/python/site-packages/visdom/__init__.py", line 720, in _handle_post
    r = self.session.post(url, data=data)
  File "/Users/visriv/Library/Python/3.9/lib/python/site-packages/requests/sessions.py", line 635, in post
    return self.request("POST", url, data=data, json=json, **kwargs)
  File "/Users/visriv/Library/Python/3.9/lib/python/site-packages/requests/sessions.py", line 587, in request
    resp = self.send(prep, **send_kwargs)
  File "/Users/visriv/Library/Python/3.9/lib/python/site-packages/requests/sessions.py", line 701, in send
    r = adapter.send(request, **kwargs)
  File "/Users/visriv/Library/Python/3.9/lib/python/site-packages/requests/adapters.py", line 565, in send
    raise ConnectionError(e, request=request)
requests.exceptions.ConnectionError: HTTPConnectionPool(host='localhost', port=4500): Max retries exceeded with url: /events (Caused by NewConnectionError('<urllib3.connection.HTTPConnection object at 0x13fa39c10>: Failed to establish a new connection: [Errno 61] Connection refused'))
171
172
173
174
175
176
177
178
179
180
181
182
183
184
185
186
187
188
189
190
191
192
193
194
195
196
197
198
199
200
[iteration 200] time: 0.04 	beta 1.00 	lambda 0.00 training ELBO: -158.8812 (-167.4377)
Exception in user code:
------------------------------------------------------------
Active units: 0,1,2,3,4,5,6,7,8,9
Number of active units: 10/10
201
202
203
204
205
206
207
208
209
210
211
212
213
214
215
216
217
218
219
220
221
222
223
224
225
226
227
228
229
230
231
232
233
234
235
236
237
238
239
240
241
242
243
244
245
246
247
248
249
250
251
252
253
254
255
256
257
258
259
260
261
262
263
264
265
266
267
268
269
270
271
272
273
274
275
276
277
278
279
280
281
282
283
284
285
286
287
288
289
290
291
292
293
294
295
296
297
298
299
300
[iteration 300] time: 0.04 	beta 1.00 	lambda 0.00 training ELBO: -138.4534 (-148.8916)
Exception in user code:
------------------------------------------------------------
Traceback (most recent call last):
  File "/Users/visriv/Library/Python/3.9/lib/python/site-packages/urllib3/connection.py", line 174, in _new_conn
    conn = connection.create_connection(
  File "/Users/visriv/Library/Python/3.9/lib/python/site-packages/urllib3/util/connection.py", line 95, in create_connection
    raise err
  File "/Users/visriv/Library/Python/3.9/lib/python/site-packages/urllib3/util/connection.py", line 85, in create_connection
    sock.connect(sa)
ConnectionRefusedError: [Errno 61] Connection refused
During handling of the above exception, another exception occurred:
Traceback (most recent call last):
  File "/Users/visriv/Library/Python/3.9/lib/python/site-packages/urllib3/connectionpool.py", line 703, in urlopen
    httplib_response = self._make_request(
  File "/Users/visriv/Library/Python/3.9/lib/python/site-packages/urllib3/connectionpool.py", line 398, in _make_request
    conn.request(method, url, **httplib_request_kw)
  File "/Users/visriv/Library/Python/3.9/lib/python/site-packages/urllib3/connection.py", line 239, in request
    super(HTTPConnection, self).request(method, url, body=body, headers=headers)
  File "/Library/Developer/CommandLineTools/Library/Frameworks/Python3.framework/Versions/3.9/lib/python3.9/http/client.py", line 1257, in request
    self._send_request(method, url, body, headers, encode_chunked)
  File "/Library/Developer/CommandLineTools/Library/Frameworks/Python3.framework/Versions/3.9/lib/python3.9/http/client.py", line 1303, in _send_request
    self.endheaders(body, encode_chunked=encode_chunked)
  File "/Library/Developer/CommandLineTools/Library/Frameworks/Python3.framework/Versions/3.9/lib/python3.9/http/client.py", line 1252, in endheaders
    self._send_output(message_body, encode_chunked=encode_chunked)
  File "/Library/Developer/CommandLineTools/Library/Frameworks/Python3.framework/Versions/3.9/lib/python3.9/http/client.py", line 1012, in _send_output
    self.send(msg)
  File "/Library/Developer/CommandLineTools/Library/Frameworks/Python3.framework/Versions/3.9/lib/python3.9/http/client.py", line 952, in send
    self.connect()
  File "/Users/visriv/Library/Python/3.9/lib/python/site-packages/urllib3/connection.py", line 205, in connect
    conn = self._new_conn()
  File "/Users/visriv/Library/Python/3.9/lib/python/site-packages/urllib3/connection.py", line 186, in _new_conn
    raise NewConnectionError(
urllib3.exceptions.NewConnectionError: <urllib3.connection.HTTPConnection object at 0x13f1c1940>: Failed to establish a new connection: [Errno 61] Connection refused
During handling of the above exception, another exception occurred:
Traceback (most recent call last):
  File "/Users/visriv/Library/Python/3.9/lib/python/site-packages/requests/adapters.py", line 489, in send
    resp = conn.urlopen(
  File "/Users/visriv/Library/Python/3.9/lib/python/site-packages/urllib3/connectionpool.py", line 787, in urlopen
    retries = retries.increment(
  File "/Users/visriv/Library/Python/3.9/lib/python/site-packages/urllib3/util/retry.py", line 592, in increment
    raise MaxRetryError(_pool, url, error or ResponseError(cause))
urllib3.exceptions.MaxRetryError: HTTPConnectionPool(host='localhost', port=4500): Max retries exceeded with url: /events (Caused by NewConnectionError('<urllib3.connection.HTTPConnection object at 0x13f1c1940>: Failed to establish a new connection: [Errno 61] Connection refused'))
During handling of the above exception, another exception occurred:
Traceback (most recent call last):
  File "/Users/visriv/Library/Python/3.9/lib/python/site-packages/visdom/__init__.py", line 756, in _send
    return self._handle_post(
  File "/Users/visriv/Library/Python/3.9/lib/python/site-packages/visdom/__init__.py", line 720, in _handle_post
    r = self.session.post(url, data=data)
  File "/Users/visriv/Library/Python/3.9/lib/python/site-packages/requests/sessions.py", line 635, in post
    return self.request("POST", url, data=data, json=json, **kwargs)
  File "/Users/visriv/Library/Python/3.9/lib/python/site-packages/requests/sessions.py", line 587, in request
    resp = self.send(prep, **send_kwargs)
  File "/Users/visriv/Library/Python/3.9/lib/python/site-packages/requests/sessions.py", line 701, in send
    r = adapter.send(request, **kwargs)
  File "/Users/visriv/Library/Python/3.9/lib/python/site-packages/requests/adapters.py", line 565, in send
    raise ConnectionError(e, request=request)
requests.exceptions.ConnectionError: HTTPConnectionPool(host='localhost', port=4500): Max retries exceeded with url: /events (Caused by NewConnectionError('<urllib3.connection.HTTPConnection object at 0x13f1c1940>: Failed to establish a new connection: [Errno 61] Connection refused'))
Active units: 0,1,2,3,4,5,6,7,8,9
Number of active units: 10/10
301
302
303
304
305
306
307
308
309
310
311
312
313
314
315
316
317
318
319
320
321
322
323
324
325
326
327
328
329
330
331
332
333
334
335
336
337
338
339
340
341
342
343
344
345
346
347
348
349
350
351
352
353
354
355
356
357
358
359
360
361
362
363
364
365
366
367
368
369
370
371
372
373
374
375
376
377
378
379
380
381
382
383
384
385
386
387
388
389
390
391
392
393
394
395
396
397
398
399
400
[iteration 400] time: 0.04 	beta 1.00 	lambda 0.00 training ELBO: -134.3830 (-140.1596)
Exception in user code:
------------------------------------------------------------
Traceback (most recent call last):
  File "/Users/visriv/Library/Python/3.9/lib/python/site-packages/urllib3/connection.py", line 174, in _new_conn
    conn = connection.create_connection(
  File "/Users/visriv/Library/Python/3.9/lib/python/site-packages/urllib3/util/connection.py", line 95, in create_connection
    raise err
  File "/Users/visriv/Library/Python/3.9/lib/python/site-packages/urllib3/util/connection.py", line 85, in create_connection
    sock.connect(sa)
ConnectionRefusedError: [Errno 61] Connection refused
During handling of the above exception, another exception occurred:
Traceback (most recent call last):
  File "/Users/visriv/Library/Python/3.9/lib/python/site-packages/urllib3/connectionpool.py", line 703, in urlopen
    httplib_response = self._make_request(
  File "/Users/visriv/Library/Python/3.9/lib/python/site-packages/urllib3/connectionpool.py", line 398, in _make_request
    conn.request(method, url, **httplib_request_kw)
  File "/Users/visriv/Library/Python/3.9/lib/python/site-packages/urllib3/connection.py", line 239, in request
    super(HTTPConnection, self).request(method, url, body=body, headers=headers)
  File "/Library/Developer/CommandLineTools/Library/Frameworks/Python3.framework/Versions/3.9/lib/python3.9/http/client.py", line 1257, in request
    self._send_request(method, url, body, headers, encode_chunked)
  File "/Library/Developer/CommandLineTools/Library/Frameworks/Python3.framework/Versions/3.9/lib/python3.9/http/client.py", line 1303, in _send_request
    self.endheaders(body, encode_chunked=encode_chunked)
  File "/Library/Developer/CommandLineTools/Library/Frameworks/Python3.framework/Versions/3.9/lib/python3.9/http/client.py", line 1252, in endheaders
    self._send_output(message_body, encode_chunked=encode_chunked)
  File "/Library/Developer/CommandLineTools/Library/Frameworks/Python3.framework/Versions/3.9/lib/python3.9/http/client.py", line 1012, in _send_output
    self.send(msg)
  File "/Library/Developer/CommandLineTools/Library/Frameworks/Python3.framework/Versions/3.9/lib/python3.9/http/client.py", line 952, in send
    self.connect()
  File "/Users/visriv/Library/Python/3.9/lib/python/site-packages/urllib3/connection.py", line 205, in connect
    conn = self._new_conn()
  File "/Users/visriv/Library/Python/3.9/lib/python/site-packages/urllib3/connection.py", line 186, in _new_conn
    raise NewConnectionError(
urllib3.exceptions.NewConnectionError: <urllib3.connection.HTTPConnection object at 0x13ed8cfd0>: Failed to establish a new connection: [Errno 61] Connection refused
During handling of the above exception, another exception occurred:
Traceback (most recent call last):
  File "/Users/visriv/Library/Python/3.9/lib/python/site-packages/requests/adapters.py", line 489, in send
    resp = conn.urlopen(
  File "/Users/visriv/Library/Python/3.9/lib/python/site-packages/urllib3/connectionpool.py", line 787, in urlopen
    retries = retries.increment(
  File "/Users/visriv/Library/Python/3.9/lib/python/site-packages/urllib3/util/retry.py", line 592, in increment
    raise MaxRetryError(_pool, url, error or ResponseError(cause))
urllib3.exceptions.MaxRetryError: HTTPConnectionPool(host='localhost', port=4500): Max retries exceeded with url: /events (Caused by NewConnectionError('<urllib3.connection.HTTPConnection object at 0x13ed8cfd0>: Failed to establish a new connection: [Errno 61] Connection refused'))
During handling of the above exception, another exception occurred:
Traceback (most recent call last):
  File "/Users/visriv/Library/Python/3.9/lib/python/site-packages/visdom/__init__.py", line 756, in _send
    return self._handle_post(
  File "/Users/visriv/Library/Python/3.9/lib/python/site-packages/visdom/__init__.py", line 720, in _handle_post
    r = self.session.post(url, data=data)
  File "/Users/visriv/Library/Python/3.9/lib/python/site-packages/requests/sessions.py", line 635, in post
    return self.request("POST", url, data=data, json=json, **kwargs)
  File "/Users/visriv/Library/Python/3.9/lib/python/site-packages/requests/sessions.py", line 587, in request
    resp = self.send(prep, **send_kwargs)
  File "/Users/visriv/Library/Python/3.9/lib/python/site-packages/requests/sessions.py", line 701, in send
    r = adapter.send(request, **kwargs)
  File "/Users/visriv/Library/Python/3.9/lib/python/site-packages/requests/adapters.py", line 565, in send
    raise ConnectionError(e, request=request)
requests.exceptions.ConnectionError: HTTPConnectionPool(host='localhost', port=4500): Max retries exceeded with url: /events (Caused by NewConnectionError('<urllib3.connection.HTTPConnection object at 0x13ed8cfd0>: Failed to establish a new connection: [Errno 61] Connection refused'))
Active units: 0,1,2,3,4,5,6,7,8,9
Number of active units: 10/10
401
402
403
404
405
406
407
408
409
410
411
412
413
414
415
416
417
418
419
420
421
422
423
424
425
426
427
428
429
430
431
432
433
434
435
436
437
438
439
440
441
442
443
444
445
446
447
448
449
450
451
452
453
454
455
456
457
458
459
460
461
462
463
464
465
466
467
468
469
470
471
472
473
474
475
476
477
478
479
480
481
482
483
484
485
486
487
488
489
490
491
492
493
494
495
496
497
498
499
500
[iteration 500] time: 0.04 	beta 1.00 	lambda 0.00 training ELBO: -131.2493 (-135.5846)
Exception in user code:
------------------------------------------------------------
Traceback (most recent call last):
  File "/Users/visriv/Library/Python/3.9/lib/python/site-packages/urllib3/connection.py", line 174, in _new_conn
    conn = connection.create_connection(
  File "/Users/visriv/Library/Python/3.9/lib/python/site-packages/urllib3/util/connection.py", line 95, in create_connection
    raise err
  File "/Users/visriv/Library/Python/3.9/lib/python/site-packages/urllib3/util/connection.py", line 85, in create_connection
    sock.connect(sa)
ConnectionRefusedError: [Errno 61] Connection refused
During handling of the above exception, another exception occurred:
Traceback (most recent call last):
  File "/Users/visriv/Library/Python/3.9/lib/python/site-packages/urllib3/connectionpool.py", line 703, in urlopen
    httplib_response = self._make_request(
  File "/Users/visriv/Library/Python/3.9/lib/python/site-packages/urllib3/connectionpool.py", line 398, in _make_request
    conn.request(method, url, **httplib_request_kw)
  File "/Users/visriv/Library/Python/3.9/lib/python/site-packages/urllib3/connection.py", line 239, in request
    super(HTTPConnection, self).request(method, url, body=body, headers=headers)
  File "/Library/Developer/CommandLineTools/Library/Frameworks/Python3.framework/Versions/3.9/lib/python3.9/http/client.py", line 1257, in request
    self._send_request(method, url, body, headers, encode_chunked)
  File "/Library/Developer/CommandLineTools/Library/Frameworks/Python3.framework/Versions/3.9/lib/python3.9/http/client.py", line 1303, in _send_request
    self.endheaders(body, encode_chunked=encode_chunked)
  File "/Library/Developer/CommandLineTools/Library/Frameworks/Python3.framework/Versions/3.9/lib/python3.9/http/client.py", line 1252, in endheaders
    self._send_output(message_body, encode_chunked=encode_chunked)
  File "/Library/Developer/CommandLineTools/Library/Frameworks/Python3.framework/Versions/3.9/lib/python3.9/http/client.py", line 1012, in _send_output
    self.send(msg)
  File "/Library/Developer/CommandLineTools/Library/Frameworks/Python3.framework/Versions/3.9/lib/python3.9/http/client.py", line 952, in send
    self.connect()
  File "/Users/visriv/Library/Python/3.9/lib/python/site-packages/urllib3/connection.py", line 205, in connect
    conn = self._new_conn()
  File "/Users/visriv/Library/Python/3.9/lib/python/site-packages/urllib3/connection.py", line 186, in _new_conn
    raise NewConnectionError(
urllib3.exceptions.NewConnectionError: <urllib3.connection.HTTPConnection object at 0x1400be790>: Failed to establish a new connection: [Errno 61] Connection refused
During handling of the above exception, another exception occurred:
Traceback (most recent call last):
  File "/Users/visriv/Library/Python/3.9/lib/python/site-packages/requests/adapters.py", line 489, in send
    resp = conn.urlopen(
  File "/Users/visriv/Library/Python/3.9/lib/python/site-packages/urllib3/connectionpool.py", line 787, in urlopen
    retries = retries.increment(
  File "/Users/visriv/Library/Python/3.9/lib/python/site-packages/urllib3/util/retry.py", line 592, in increment
    raise MaxRetryError(_pool, url, error or ResponseError(cause))
urllib3.exceptions.MaxRetryError: HTTPConnectionPool(host='localhost', port=4500): Max retries exceeded with url: /events (Caused by NewConnectionError('<urllib3.connection.HTTPConnection object at 0x1400be790>: Failed to establish a new connection: [Errno 61] Connection refused'))
During handling of the above exception, another exception occurred:
Traceback (most recent call last):
  File "/Users/visriv/Library/Python/3.9/lib/python/site-packages/visdom/__init__.py", line 756, in _send
    return self._handle_post(
  File "/Users/visriv/Library/Python/3.9/lib/python/site-packages/visdom/__init__.py", line 720, in _handle_post
    r = self.session.post(url, data=data)
  File "/Users/visriv/Library/Python/3.9/lib/python/site-packages/requests/sessions.py", line 635, in post
    return self.request("POST", url, data=data, json=json, **kwargs)
  File "/Users/visriv/Library/Python/3.9/lib/python/site-packages/requests/sessions.py", line 587, in request
    resp = self.send(prep, **send_kwargs)
  File "/Users/visriv/Library/Python/3.9/lib/python/site-packages/requests/sessions.py", line 701, in send
    r = adapter.send(request, **kwargs)
  File "/Users/visriv/Library/Python/3.9/lib/python/site-packages/requests/adapters.py", line 565, in send
    raise ConnectionError(e, request=request)
requests.exceptions.ConnectionError: HTTPConnectionPool(host='localhost', port=4500): Max retries exceeded with url: /events (Caused by NewConnectionError('<urllib3.connection.HTTPConnection object at 0x1400be790>: Failed to establish a new connection: [Errno 61] Connection refused'))
Active units: 0,1,2,3,4,5,6,7,8,9
Number of active units: 10/10
501
502
503
504
505
506
507
508
509
510
511
512
513
514
515
516
517
518
519
520
521
522
523
524
525
526
527
528
529
530
531
532
533
534
535
536
537
538
539
540
541
542
543
544
545
546
547
548
549
550
551
552
553
554
555
556
557
558
559
560
561
562
563
564
565
566
567
568
569
570
571
572
573
574
575
576
577
578
579
580
581
582
583
584
585
586
587
588
589
590
591
592
593
594
595
596
597
598
599
600
[iteration 600] time: 0.04 	beta 1.00 	lambda 0.00 training ELBO: -130.0562 (-132.4281)
Exception in user code:
------------------------------------------------------------
Traceback (most recent call last):
  File "/Users/visriv/Library/Python/3.9/lib/python/site-packages/urllib3/connection.py", line 174, in _new_conn
    conn = connection.create_connection(
  File "/Users/visriv/Library/Python/3.9/lib/python/site-packages/urllib3/util/connection.py", line 95, in create_connection
    raise err
  File "/Users/visriv/Library/Python/3.9/lib/python/site-packages/urllib3/util/connection.py", line 85, in create_connection
    sock.connect(sa)
ConnectionRefusedError: [Errno 61] Connection refused
During handling of the above exception, another exception occurred:
Traceback (most recent call last):
  File "/Users/visriv/Library/Python/3.9/lib/python/site-packages/urllib3/connectionpool.py", line 703, in urlopen
    httplib_response = self._make_request(
  File "/Users/visriv/Library/Python/3.9/lib/python/site-packages/urllib3/connectionpool.py", line 398, in _make_request
    conn.request(method, url, **httplib_request_kw)
  File "/Users/visriv/Library/Python/3.9/lib/python/site-packages/urllib3/connection.py", line 239, in request
    super(HTTPConnection, self).request(method, url, body=body, headers=headers)
  File "/Library/Developer/CommandLineTools/Library/Frameworks/Python3.framework/Versions/3.9/lib/python3.9/http/client.py", line 1257, in request
    self._send_request(method, url, body, headers, encode_chunked)
  File "/Library/Developer/CommandLineTools/Library/Frameworks/Python3.framework/Versions/3.9/lib/python3.9/http/client.py", line 1303, in _send_request
    self.endheaders(body, encode_chunked=encode_chunked)
  File "/Library/Developer/CommandLineTools/Library/Frameworks/Python3.framework/Versions/3.9/lib/python3.9/http/client.py", line 1252, in endheaders
    self._send_output(message_body, encode_chunked=encode_chunked)
  File "/Library/Developer/CommandLineTools/Library/Frameworks/Python3.framework/Versions/3.9/lib/python3.9/http/client.py", line 1012, in _send_output
    self.send(msg)
  File "/Library/Developer/CommandLineTools/Library/Frameworks/Python3.framework/Versions/3.9/lib/python3.9/http/client.py", line 952, in send
    self.connect()
  File "/Users/visriv/Library/Python/3.9/lib/python/site-packages/urllib3/connection.py", line 205, in connect
    conn = self._new_conn()
  File "/Users/visriv/Library/Python/3.9/lib/python/site-packages/urllib3/connection.py", line 186, in _new_conn
    raise NewConnectionError(
urllib3.exceptions.NewConnectionError: <urllib3.connection.HTTPConnection object at 0x13f380b50>: Failed to establish a new connection: [Errno 61] Connection refused
During handling of the above exception, another exception occurred:
Traceback (most recent call last):
  File "/Users/visriv/Library/Python/3.9/lib/python/site-packages/requests/adapters.py", line 489, in send
    resp = conn.urlopen(
  File "/Users/visriv/Library/Python/3.9/lib/python/site-packages/urllib3/connectionpool.py", line 787, in urlopen
    retries = retries.increment(
  File "/Users/visriv/Library/Python/3.9/lib/python/site-packages/urllib3/util/retry.py", line 592, in increment
    raise MaxRetryError(_pool, url, error or ResponseError(cause))
urllib3.exceptions.MaxRetryError: HTTPConnectionPool(host='localhost', port=4500): Max retries exceeded with url: /events (Caused by NewConnectionError('<urllib3.connection.HTTPConnection object at 0x13f380b50>: Failed to establish a new connection: [Errno 61] Connection refused'))
During handling of the above exception, another exception occurred:
Traceback (most recent call last):
  File "/Users/visriv/Library/Python/3.9/lib/python/site-packages/visdom/__init__.py", line 756, in _send
    return self._handle_post(
  File "/Users/visriv/Library/Python/3.9/lib/python/site-packages/visdom/__init__.py", line 720, in _handle_post
    r = self.session.post(url, data=data)
  File "/Users/visriv/Library/Python/3.9/lib/python/site-packages/requests/sessions.py", line 635, in post
    return self.request("POST", url, data=data, json=json, **kwargs)
  File "/Users/visriv/Library/Python/3.9/lib/python/site-packages/requests/sessions.py", line 587, in request
    resp = self.send(prep, **send_kwargs)
  File "/Users/visriv/Library/Python/3.9/lib/python/site-packages/requests/sessions.py", line 701, in send
    r = adapter.send(request, **kwargs)
  File "/Users/visriv/Library/Python/3.9/lib/python/site-packages/requests/adapters.py", line 565, in send
    raise ConnectionError(e, request=request)
requests.exceptions.ConnectionError: HTTPConnectionPool(host='localhost', port=4500): Max retries exceeded with url: /events (Caused by NewConnectionError('<urllib3.connection.HTTPConnection object at 0x13f380b50>: Failed to establish a new connection: [Errno 61] Connection refused'))
Active units: 0,1,2,3,4,5,6,7,8,9
Number of active units: 10/10
601
602
603
604
605
606
607
608
609
610
611
612
613
614
615
616
617
618
619
620
621
622
623
624
625
626
627
628
629
630
631
632
633
634
635
636
637
638
639
640
641
642
643
644
645
646
647
648
649
650
651
652
653
654
655
656
657
658
659
660
661
662
663
664
665
666
667
668
669
670
671
672
673
674
675
676
677
678
679
680
681
682
683
684
685
686
687
688
689
690
691
692
693
694
695
696
697
698
699
700
[iteration 700] time: 0.05 	beta 1.00 	lambda 0.00 training ELBO: -133.3595 (-129.7520)
Exception in user code:
------------------------------------------------------------
Traceback (most recent call last):
  File "/Users/visriv/Library/Python/3.9/lib/python/site-packages/urllib3/connection.py", line 174, in _new_conn
    conn = connection.create_connection(
  File "/Users/visriv/Library/Python/3.9/lib/python/site-packages/urllib3/util/connection.py", line 95, in create_connection
    raise err
  File "/Users/visriv/Library/Python/3.9/lib/python/site-packages/urllib3/util/connection.py", line 85, in create_connection
    sock.connect(sa)
ConnectionRefusedError: [Errno 61] Connection refused
During handling of the above exception, another exception occurred:
Traceback (most recent call last):
  File "/Users/visriv/Library/Python/3.9/lib/python/site-packages/urllib3/connectionpool.py", line 703, in urlopen
    httplib_response = self._make_request(
  File "/Users/visriv/Library/Python/3.9/lib/python/site-packages/urllib3/connectionpool.py", line 398, in _make_request
    conn.request(method, url, **httplib_request_kw)
  File "/Users/visriv/Library/Python/3.9/lib/python/site-packages/urllib3/connection.py", line 239, in request
    super(HTTPConnection, self).request(method, url, body=body, headers=headers)
  File "/Library/Developer/CommandLineTools/Library/Frameworks/Python3.framework/Versions/3.9/lib/python3.9/http/client.py", line 1257, in request
    self._send_request(method, url, body, headers, encode_chunked)
  File "/Library/Developer/CommandLineTools/Library/Frameworks/Python3.framework/Versions/3.9/lib/python3.9/http/client.py", line 1303, in _send_request
    self.endheaders(body, encode_chunked=encode_chunked)
  File "/Library/Developer/CommandLineTools/Library/Frameworks/Python3.framework/Versions/3.9/lib/python3.9/http/client.py", line 1252, in endheaders
    self._send_output(message_body, encode_chunked=encode_chunked)
  File "/Library/Developer/CommandLineTools/Library/Frameworks/Python3.framework/Versions/3.9/lib/python3.9/http/client.py", line 1012, in _send_output
    self.send(msg)
  File "/Library/Developer/CommandLineTools/Library/Frameworks/Python3.framework/Versions/3.9/lib/python3.9/http/client.py", line 952, in send
    self.connect()
  File "/Users/visriv/Library/Python/3.9/lib/python/site-packages/urllib3/connection.py", line 205, in connect
    conn = self._new_conn()
  File "/Users/visriv/Library/Python/3.9/lib/python/site-packages/urllib3/connection.py", line 186, in _new_conn
    raise NewConnectionError(
urllib3.exceptions.NewConnectionError: <urllib3.connection.HTTPConnection object at 0x13fbc8fa0>: Failed to establish a new connection: [Errno 61] Connection refused
During handling of the above exception, another exception occurred:
Traceback (most recent call last):
  File "/Users/visriv/Library/Python/3.9/lib/python/site-packages/requests/adapters.py", line 489, in send
    resp = conn.urlopen(
  File "/Users/visriv/Library/Python/3.9/lib/python/site-packages/urllib3/connectionpool.py", line 787, in urlopen
    retries = retries.increment(
  File "/Users/visriv/Library/Python/3.9/lib/python/site-packages/urllib3/util/retry.py", line 592, in increment
    raise MaxRetryError(_pool, url, error or ResponseError(cause))
urllib3.exceptions.MaxRetryError: HTTPConnectionPool(host='localhost', port=4500): Max retries exceeded with url: /events (Caused by NewConnectionError('<urllib3.connection.HTTPConnection object at 0x13fbc8fa0>: Failed to establish a new connection: [Errno 61] Connection refused'))
During handling of the above exception, another exception occurred:
Traceback (most recent call last):
  File "/Users/visriv/Library/Python/3.9/lib/python/site-packages/visdom/__init__.py", line 756, in _send
    return self._handle_post(
  File "/Users/visriv/Library/Python/3.9/lib/python/site-packages/visdom/__init__.py", line 720, in _handle_post
    r = self.session.post(url, data=data)
  File "/Users/visriv/Library/Python/3.9/lib/python/site-packages/requests/sessions.py", line 635, in post
    return self.request("POST", url, data=data, json=json, **kwargs)
  File "/Users/visriv/Library/Python/3.9/lib/python/site-packages/requests/sessions.py", line 587, in request
    resp = self.send(prep, **send_kwargs)
  File "/Users/visriv/Library/Python/3.9/lib/python/site-packages/requests/sessions.py", line 701, in send
    r = adapter.send(request, **kwargs)
  File "/Users/visriv/Library/Python/3.9/lib/python/site-packages/requests/adapters.py", line 565, in send
    raise ConnectionError(e, request=request)
requests.exceptions.ConnectionError: HTTPConnectionPool(host='localhost', port=4500): Max retries exceeded with url: /events (Caused by NewConnectionError('<urllib3.connection.HTTPConnection object at 0x13fbc8fa0>: Failed to establish a new connection: [Errno 61] Connection refused'))
Active units: 0,1,2,3,4,5,6,7,8,9
Number of active units: 10/10
701
702
703
704
705
706
707
708
709
710
711
712
713
714
715
716
717
718
719
720
721
722
723
724
725
726
727
728
729
730
731
732
733
734
735
736
737
738
739
740
741
742
743
744
745
746
747
748
749
750
751
752
753
754
755
756
757
758
759
760
761
762
763
764
765
766
767
768
769
770
771
772
773
774
775
776
777
778
779
780
781
782
783
784
785
786
787
788
789
790
791
792
793
794
795
796
797
798
799
800
[iteration 800] time: 0.04 	beta 1.00 	lambda 0.00 training ELBO: -138.5703 (-129.3367)
Exception in user code:
------------------------------------------------------------
Traceback (most recent call last):
  File "/Users/visriv/Library/Python/3.9/lib/python/site-packages/urllib3/connection.py", line 174, in _new_conn
    conn = connection.create_connection(
  File "/Users/visriv/Library/Python/3.9/lib/python/site-packages/urllib3/util/connection.py", line 95, in create_connection
    raise err
  File "/Users/visriv/Library/Python/3.9/lib/python/site-packages/urllib3/util/connection.py", line 85, in create_connection
    sock.connect(sa)
ConnectionRefusedError: [Errno 61] Connection refused
During handling of the above exception, another exception occurred:
Traceback (most recent call last):
  File "/Users/visriv/Library/Python/3.9/lib/python/site-packages/urllib3/connectionpool.py", line 703, in urlopen
    httplib_response = self._make_request(
  File "/Users/visriv/Library/Python/3.9/lib/python/site-packages/urllib3/connectionpool.py", line 398, in _make_request
    conn.request(method, url, **httplib_request_kw)
  File "/Users/visriv/Library/Python/3.9/lib/python/site-packages/urllib3/connection.py", line 239, in request
    super(HTTPConnection, self).request(method, url, body=body, headers=headers)
  File "/Library/Developer/CommandLineTools/Library/Frameworks/Python3.framework/Versions/3.9/lib/python3.9/http/client.py", line 1257, in request
    self._send_request(method, url, body, headers, encode_chunked)
  File "/Library/Developer/CommandLineTools/Library/Frameworks/Python3.framework/Versions/3.9/lib/python3.9/http/client.py", line 1303, in _send_request
    self.endheaders(body, encode_chunked=encode_chunked)
  File "/Library/Developer/CommandLineTools/Library/Frameworks/Python3.framework/Versions/3.9/lib/python3.9/http/client.py", line 1252, in endheaders
    self._send_output(message_body, encode_chunked=encode_chunked)
  File "/Library/Developer/CommandLineTools/Library/Frameworks/Python3.framework/Versions/3.9/lib/python3.9/http/client.py", line 1012, in _send_output
    self.send(msg)
  File "/Library/Developer/CommandLineTools/Library/Frameworks/Python3.framework/Versions/3.9/lib/python3.9/http/client.py", line 952, in send
    self.connect()
  File "/Users/visriv/Library/Python/3.9/lib/python/site-packages/urllib3/connection.py", line 205, in connect
    conn = self._new_conn()
  File "/Users/visriv/Library/Python/3.9/lib/python/site-packages/urllib3/connection.py", line 186, in _new_conn
    raise NewConnectionError(
urllib3.exceptions.NewConnectionError: <urllib3.connection.HTTPConnection object at 0x13f231b20>: Failed to establish a new connection: [Errno 61] Connection refused
During handling of the above exception, another exception occurred:
Traceback (most recent call last):
  File "/Users/visriv/Library/Python/3.9/lib/python/site-packages/requests/adapters.py", line 489, in send
    resp = conn.urlopen(
  File "/Users/visriv/Library/Python/3.9/lib/python/site-packages/urllib3/connectionpool.py", line 787, in urlopen
    retries = retries.increment(
  File "/Users/visriv/Library/Python/3.9/lib/python/site-packages/urllib3/util/retry.py", line 592, in increment
    raise MaxRetryError(_pool, url, error or ResponseError(cause))
urllib3.exceptions.MaxRetryError: HTTPConnectionPool(host='localhost', port=4500): Max retries exceeded with url: /events (Caused by NewConnectionError('<urllib3.connection.HTTPConnection object at 0x13f231b20>: Failed to establish a new connection: [Errno 61] Connection refused'))
During handling of the above exception, another exception occurred:
Traceback (most recent call last):
  File "/Users/visriv/Library/Python/3.9/lib/python/site-packages/visdom/__init__.py", line 756, in _send
    return self._handle_post(
  File "/Users/visriv/Library/Python/3.9/lib/python/site-packages/visdom/__init__.py", line 720, in _handle_post
    r = self.session.post(url, data=data)
  File "/Users/visriv/Library/Python/3.9/lib/python/site-packages/requests/sessions.py", line 635, in post
    return self.request("POST", url, data=data, json=json, **kwargs)
  File "/Users/visriv/Library/Python/3.9/lib/python/site-packages/requests/sessions.py", line 587, in request
    resp = self.send(prep, **send_kwargs)
  File "/Users/visriv/Library/Python/3.9/lib/python/site-packages/requests/sessions.py", line 701, in send
    r = adapter.send(request, **kwargs)
  File "/Users/visriv/Library/Python/3.9/lib/python/site-packages/requests/adapters.py", line 565, in send
    raise ConnectionError(e, request=request)
requests.exceptions.ConnectionError: HTTPConnectionPool(host='localhost', port=4500): Max retries exceeded with url: /events (Caused by NewConnectionError('<urllib3.connection.HTTPConnection object at 0x13f231b20>: Failed to establish a new connection: [Errno 61] Connection refused'))
Active units: 0,1,2,3,4,5,6,7,8,9
Number of active units: 10/10
801
802
803
804
805
806
807
808
809
810
811
812
813
814
815
816
817
818
819
820
821
822
823
824
825
826
827
828
829
830
831
832
833
834
835
836
837
838
839
840
841
842
843
844
845
846
847
848
849
850
851
852
853
854
855
856
857
858
859
860
861
862
863
864
865
866
867
868
869
870
871
872
873
874
875
876
877
878
879
880
881
882
883
884
885
886
887
888
889
890
891
892
893
894
895
896
897
898
899
900
[iteration 900] time: 0.05 	beta 1.00 	lambda 0.00 training ELBO: -133.3714 (-127.0354)
Exception in user code:
------------------------------------------------------------
Traceback (most recent call last):
  File "/Users/visriv/Library/Python/3.9/lib/python/site-packages/urllib3/connection.py", line 174, in _new_conn
    conn = connection.create_connection(
  File "/Users/visriv/Library/Python/3.9/lib/python/site-packages/urllib3/util/connection.py", line 95, in create_connection
    raise err
  File "/Users/visriv/Library/Python/3.9/lib/python/site-packages/urllib3/util/connection.py", line 85, in create_connection
    sock.connect(sa)
ConnectionRefusedError: [Errno 61] Connection refused
During handling of the above exception, another exception occurred:
Traceback (most recent call last):
  File "/Users/visriv/Library/Python/3.9/lib/python/site-packages/urllib3/connectionpool.py", line 703, in urlopen
    httplib_response = self._make_request(
  File "/Users/visriv/Library/Python/3.9/lib/python/site-packages/urllib3/connectionpool.py", line 398, in _make_request
    conn.request(method, url, **httplib_request_kw)
  File "/Users/visriv/Library/Python/3.9/lib/python/site-packages/urllib3/connection.py", line 239, in request
    super(HTTPConnection, self).request(method, url, body=body, headers=headers)
  File "/Library/Developer/CommandLineTools/Library/Frameworks/Python3.framework/Versions/3.9/lib/python3.9/http/client.py", line 1257, in request
    self._send_request(method, url, body, headers, encode_chunked)
  File "/Library/Developer/CommandLineTools/Library/Frameworks/Python3.framework/Versions/3.9/lib/python3.9/http/client.py", line 1303, in _send_request
    self.endheaders(body, encode_chunked=encode_chunked)
  File "/Library/Developer/CommandLineTools/Library/Frameworks/Python3.framework/Versions/3.9/lib/python3.9/http/client.py", line 1252, in endheaders
    self._send_output(message_body, encode_chunked=encode_chunked)
  File "/Library/Developer/CommandLineTools/Library/Frameworks/Python3.framework/Versions/3.9/lib/python3.9/http/client.py", line 1012, in _send_output
    self.send(msg)
  File "/Library/Developer/CommandLineTools/Library/Frameworks/Python3.framework/Versions/3.9/lib/python3.9/http/client.py", line 952, in send
    self.connect()
  File "/Users/visriv/Library/Python/3.9/lib/python/site-packages/urllib3/connection.py", line 205, in connect
    conn = self._new_conn()
  File "/Users/visriv/Library/Python/3.9/lib/python/site-packages/urllib3/connection.py", line 186, in _new_conn
    raise NewConnectionError(
urllib3.exceptions.NewConnectionError: <urllib3.connection.HTTPConnection object at 0x140068190>: Failed to establish a new connection: [Errno 61] Connection refused
During handling of the above exception, another exception occurred:
Traceback (most recent call last):
  File "/Users/visriv/Library/Python/3.9/lib/python/site-packages/requests/adapters.py", line 489, in send
    resp = conn.urlopen(
  File "/Users/visriv/Library/Python/3.9/lib/python/site-packages/urllib3/connectionpool.py", line 787, in urlopen
    retries = retries.increment(
  File "/Users/visriv/Library/Python/3.9/lib/python/site-packages/urllib3/util/retry.py", line 592, in increment
    raise MaxRetryError(_pool, url, error or ResponseError(cause))
urllib3.exceptions.MaxRetryError: HTTPConnectionPool(host='localhost', port=4500): Max retries exceeded with url: /events (Caused by NewConnectionError('<urllib3.connection.HTTPConnection object at 0x140068190>: Failed to establish a new connection: [Errno 61] Connection refused'))
During handling of the above exception, another exception occurred:
Traceback (most recent call last):
  File "/Users/visriv/Library/Python/3.9/lib/python/site-packages/visdom/__init__.py", line 756, in _send
    return self._handle_post(
  File "/Users/visriv/Library/Python/3.9/lib/python/site-packages/visdom/__init__.py", line 720, in _handle_post
    r = self.session.post(url, data=data)
  File "/Users/visriv/Library/Python/3.9/lib/python/site-packages/requests/sessions.py", line 635, in post
    return self.request("POST", url, data=data, json=json, **kwargs)
  File "/Users/visriv/Library/Python/3.9/lib/python/site-packages/requests/sessions.py", line 587, in request
    resp = self.send(prep, **send_kwargs)
  File "/Users/visriv/Library/Python/3.9/lib/python/site-packages/requests/sessions.py", line 701, in send
    r = adapter.send(request, **kwargs)
  File "/Users/visriv/Library/Python/3.9/lib/python/site-packages/requests/adapters.py", line 565, in send
    raise ConnectionError(e, request=request)
requests.exceptions.ConnectionError: HTTPConnectionPool(host='localhost', port=4500): Max retries exceeded with url: /events (Caused by NewConnectionError('<urllib3.connection.HTTPConnection object at 0x140068190>: Failed to establish a new connection: [Errno 61] Connection refused'))
Active units: 0,1,2,3,4,5,6,7,8,9
Number of active units: 10/10
901
902
903
904
905
906
907
908
909
910
911
912
913
914
915
916
917
918
919
920
921
922
923
924
925
926
927
928
929
930
931
932
933
934
935
936
937
938
939
940
941
942
943
944
945
946
947
948
949
950
951
952
953
954
955
956
957
958
959
960
961
962
963
964
965
966
967
968
969
970
971
972
973
974
975
976
977
978
979
980
981
982
983
984
985
986
987
988
989
990
991
992
993
994
995
996
997
998
999
1000
[iteration 1000] time: 0.05 	beta 1.00 	lambda 0.00 training ELBO: -133.3751 (-125.6438)
Exception in user code:
------------------------------------------------------------
Traceback (most recent call last):
  File "/Users/visriv/Library/Python/3.9/lib/python/site-packages/urllib3/connection.py", line 174, in _new_conn
    conn = connection.create_connection(
  File "/Users/visriv/Library/Python/3.9/lib/python/site-packages/urllib3/util/connection.py", line 95, in create_connection
    raise err
  File "/Users/visriv/Library/Python/3.9/lib/python/site-packages/urllib3/util/connection.py", line 85, in create_connection
    sock.connect(sa)
ConnectionRefusedError: [Errno 61] Connection refused
During handling of the above exception, another exception occurred:
Traceback (most recent call last):
  File "/Users/visriv/Library/Python/3.9/lib/python/site-packages/urllib3/connectionpool.py", line 703, in urlopen
    httplib_response = self._make_request(
  File "/Users/visriv/Library/Python/3.9/lib/python/site-packages/urllib3/connectionpool.py", line 398, in _make_request
    conn.request(method, url, **httplib_request_kw)
  File "/Users/visriv/Library/Python/3.9/lib/python/site-packages/urllib3/connection.py", line 239, in request
    super(HTTPConnection, self).request(method, url, body=body, headers=headers)
  File "/Library/Developer/CommandLineTools/Library/Frameworks/Python3.framework/Versions/3.9/lib/python3.9/http/client.py", line 1257, in request
    self._send_request(method, url, body, headers, encode_chunked)
  File "/Library/Developer/CommandLineTools/Library/Frameworks/Python3.framework/Versions/3.9/lib/python3.9/http/client.py", line 1303, in _send_request
    self.endheaders(body, encode_chunked=encode_chunked)
  File "/Library/Developer/CommandLineTools/Library/Frameworks/Python3.framework/Versions/3.9/lib/python3.9/http/client.py", line 1252, in endheaders
    self._send_output(message_body, encode_chunked=encode_chunked)
  File "/Library/Developer/CommandLineTools/Library/Frameworks/Python3.framework/Versions/3.9/lib/python3.9/http/client.py", line 1012, in _send_output
    self.send(msg)
  File "/Library/Developer/CommandLineTools/Library/Frameworks/Python3.framework/Versions/3.9/lib/python3.9/http/client.py", line 952, in send
    self.connect()
  File "/Users/visriv/Library/Python/3.9/lib/python/site-packages/urllib3/connection.py", line 205, in connect
    conn = self._new_conn()
  File "/Users/visriv/Library/Python/3.9/lib/python/site-packages/urllib3/connection.py", line 186, in _new_conn
    raise NewConnectionError(
urllib3.exceptions.NewConnectionError: <urllib3.connection.HTTPConnection object at 0x1402e7a00>: Failed to establish a new connection: [Errno 61] Connection refused
During handling of the above exception, another exception occurred:
Traceback (most recent call last):
  File "/Users/visriv/Library/Python/3.9/lib/python/site-packages/requests/adapters.py", line 489, in send
    resp = conn.urlopen(
  File "/Users/visriv/Library/Python/3.9/lib/python/site-packages/urllib3/connectionpool.py", line 787, in urlopen
    retries = retries.increment(
  File "/Users/visriv/Library/Python/3.9/lib/python/site-packages/urllib3/util/retry.py", line 592, in increment
    raise MaxRetryError(_pool, url, error or ResponseError(cause))
urllib3.exceptions.MaxRetryError: HTTPConnectionPool(host='localhost', port=4500): Max retries exceeded with url: /events (Caused by NewConnectionError('<urllib3.connection.HTTPConnection object at 0x1402e7a00>: Failed to establish a new connection: [Errno 61] Connection refused'))
During handling of the above exception, another exception occurred:
Traceback (most recent call last):
  File "/Users/visriv/Library/Python/3.9/lib/python/site-packages/visdom/__init__.py", line 756, in _send
    return self._handle_post(
  File "/Users/visriv/Library/Python/3.9/lib/python/site-packages/visdom/__init__.py", line 720, in _handle_post
    r = self.session.post(url, data=data)
  File "/Users/visriv/Library/Python/3.9/lib/python/site-packages/requests/sessions.py", line 635, in post
    return self.request("POST", url, data=data, json=json, **kwargs)
  File "/Users/visriv/Library/Python/3.9/lib/python/site-packages/requests/sessions.py", line 587, in request
    resp = self.send(prep, **send_kwargs)
  File "/Users/visriv/Library/Python/3.9/lib/python/site-packages/requests/sessions.py", line 701, in send
    r = adapter.send(request, **kwargs)
  File "/Users/visriv/Library/Python/3.9/lib/python/site-packages/requests/adapters.py", line 565, in send
    raise ConnectionError(e, request=request)
requests.exceptions.ConnectionError: HTTPConnectionPool(host='localhost', port=4500): Max retries exceeded with url: /events (Caused by NewConnectionError('<urllib3.connection.HTTPConnection object at 0x1402e7a00>: Failed to establish a new connection: [Errno 61] Connection refused'))
1
2
3
4
5
6
7
8
9
10
11
12
13
14
15
16
17
18
19
20
21
22
23
24
25
26
27
28
29
30
31
32
33
34
35
36
37
38
39
40
41
42
43
44
45
46
47
48
49
50
51
52
53
54
55
56
57
58
59
60
61
62
63
64
65
66
67
68
69
70
71
72
73
74
75
76
77
78
79
80
81
82
83
84
85
86
87
88
89
90
91
92
93
94
95
96
97
98
99
100
[iteration 100] time: 0.04 	beta 1.00 	lambda 0.00 training ELBO: -198.3916 (-234.3129)
Active units: 0,1,2,3,4,5,6,7,8,9
Number of active units: 10/10
101
102
103
104
105
106
107
108
109
110
111
112
113
114
115
116
117
118
119
120
121
122
123
124
125
126
127
128
129
130
131
132
133
134
135
136
137
138
139
140
141
142
143
144
145
146
147
148
149
150
151
152
153
154
155
156
157
158
159
160
161
162
163
164
165
166
167
168
169
170
171
172
173
174
175
176
177
178
179
180
181
182
183
184
185
186
187
188
189
190
191
192
193
194
195
196
197
198
199
200
[iteration 200] time: 0.04 	beta 1.00 	lambda 0.00 training ELBO: -162.4673 (-161.4889)
Active units: 0,1,2,3,4,5,6,7,8,9
Number of active units: 10/10
201
202
203
204
205
206
207
208
209
210
211
212
213
214
215
216
217
218
219
220
221
222
223
224
225
226
227
228
229
230
231
232
233
234
235
236
237
238
239
240
241
242
243
244
245
246
247
248
249
250
251
252
253
254
255
256
257
258
259
260
261
262
263
264
265
266
267
268
269
270
271
272
273
274
275
276
277
278
279
280
281
282
283
284
285
286
287
288
289
290
291
292
293
294
295
296
297
298
299
300
[iteration 300] time: 0.04 	beta 1.00 	lambda 0.00 training ELBO: -152.9952 (-149.2213)
Active units: 0,1,2,3,4,5,6,7,8,9
Number of active units: 10/10
301
302
303
304
305
306
307
308
309
310
311
312
313
314
315
316
317
318
319
320
321
322
323
324
325
326
327
328
329
330
331
332
333
334
335
336
337
338
339
340
341
342
343
344
345
346
347
348
349
350
351
352
353
354
355
356
357
358
359
360
361
362
363
364
365
366
367
368
369
370
371
372
373
374
375
376
377
378
379
380
381
382
383
384
385
386
387
388
389
390
391
392
393
394
395
396
397
398
399
400
[iteration 400] time: 0.04 	beta 1.00 	lambda 0.00 training ELBO: -139.4292 (-137.5684)
Active units: 0,1,2,3,4,5,6,7,8,9
Number of active units: 10/10
401
402
403
404
405
406
407
408
409
410
411
412
413
414
415
416
417
418
419
420
421
422
423
424
425
426
427
428
429
430
431
432
433
434
435
436
437
438
439
440
441
442
443
444
445
446
447
448
449
450
451
452
453
454
455
456
457
458
459
460
461
462
463
464
465
466
467
468
469
470
471
472
473
474
475
476
477
478
479
480
481
482
483
484
485
486
487
488
489
490
491
492
493
494
495
496
497
498
499
500
[iteration 500] time: 0.04 	beta 1.00 	lambda 0.00 training ELBO: -133.6198 (-134.9879)
Active units: 0,1,2,3,4,5,6,7,8,9
Number of active units: 10/10
501
502
503
504
505
506
507
508
509
510
511
512
513
514
515
516
517
518
519
520
521
522
523
524
525
526
527
528
529
530
531
532
533
534
535
536
537
538
539
540
541
542
543
544
545
546
547
548
549
550
551
552
553
554
555
556
557
558
559
560
561
562
563
564
565
566
567
568
569
570
571
572
573
574
575
576
577
578
579
580
581
582
583
584
585
586
587
588
589
590
591
592
593
594
595
596
597
598
599
600
[iteration 600] time: 0.08 	beta 1.00 	lambda 0.00 training ELBO: -142.1545 (-132.3344)
